Workbook
Name 주소: #REF!
Name 주소: #REF!

Sheet 스토리지-가상화현황
A1: 구분 | B1: HOSTNAME | C1: 서버명(Guest) | D1: 가상화 호스트 | E1: VG명 | F1: LUN수 | G1: Lun Size | H1: 할당량 | I1: LUN name | J1: LUN Address | K1: 사용 Port
A2: DR 파생 접속 | B2: pkvex1006 pkvex1010 pkvex1014 | C2: pkfchapr1 | D2: =VLOOKUP($C$2:$C$171,가상화배치내역!$A$2:$B$335,2,FALSE) -> pkvex1006 | E2: vg_ch1fs01 | F2: 1 | G2: 590 | H2: =F2*G2 -> 590 | I2: vg_ch1fs01 | J2: 0 | K2: 1A/2A/3A/4A/1C/2C/3C/4C
C3: pkfchapr2 | D3: =VLOOKUP($C$2:$C$171,가상화배치내역!$A$2:$B$335,2,FALSE) -> pkvex1010 | E3: vg_ch2fs01 | F3: 1 | G3: 590 | H3: =F3*G3 -> 590 | I3: vg_ch2fs01 | J3: 0.00069444444
C4: pkfchapr3 | D4: =VLOOKUP($C$2:$C$171,가상화배치내역!$A$2:$B$335,2,FALSE) -> pkvex1014 | E4: vg_ch3fs01 | F4: 1 | G4: 590 | H4: =F4*G4 -> 590 | I4: vg_ch3fs01 | J4: 0.0013888889
C5: pkfchapr1 | D5: =VLOOKUP($C$2:$C$171,가상화배치내역!$A$2:$B$335,2,FALSE) -> pkvex1006 | E5: vg_chcfs01 | F5: 1 | G5: 75 | H5: =F5*G5 -> 75 | I5: vg_chcfs01 | J5: 0.0020833333
E6: Lock Device | F6: 1 | G6: 0.2 | H6: =F6*G6 -> 0.2 | I6: Lock Device | J6: 0F:00
E7: Lock Device | F7: 1 | G7: 0.2 | H7: =F7*G7 -> 0.2 | I7: Lock Device | J7: 0F:01
E8: Lock Device | F8: 1 | G8: 0.2 | H8: =F8*G8 -> 0.2 | I8: Lock Device | J8: 0F:02
C9: pkfchapr2 | D9: =VLOOKUP($C$2:$C$171,가상화배치내역!$A$2:$B$335,2,FALSE) -> pkvex1010 | E9: vg_chcfs01 | F9: 1 | G9: 75 | H9: =F9*G9 -> 75 | I9: vg_chcfs01 | J9: 0.0020833333
E10: Lock Device | F10: 1 | G10: 0.2 | H10: =F10*G10 -> 0.2 | I10: Lock Device | J10: 0F:00
E11: Lock Device | F11: 1 | G11: 0.2 | H11: =F11*G11 -> 0.2 | I11: Lock Device | J11: 0F:01
E12: Lock Device | F12: 1 | G12: 0.2 | H12: =F12*G12 -> 0.2 | I12: Lock Device | J12: 0F:02
C13: pkfchapr3 | D13: =VLOOKUP($C$2:$C$171,가상화배치내역!$A$2:$B$335,2,FALSE) -> pkvex1014 | E13: vg_chcfs01 | F13: 1 | G13: 75 | H13: =F13*G13 -> 75 | I13: vg_chcfs01 | J13: 0.0020833333
E14: Lock Device | F14: 1 | G14: 0.2 | H14: =F14*G14 -> 0.2 | I14: Lock Device | J14: 0F:00
E15: Lock Device | F15: 1 | G15: 0.2 | H15: =F15*G15 -> 0.2 | I15: Lock Device | J15: 0F:01
E16: Lock Device | F16: 1 | G16: 0.2 | H16: =F16*G16 -> 0.2 | I16: Lock Device | J16: 0F:02
C17: pkfchapr1 | D17: =VLOOKUP($C$2:$C$171,가상화배치내역!$A$2:$B$335,2,FALSE) -> pkvex1006 | E17: VVR_vg_ch1fs01 | F17: 1 | G17: 59 | H17: =F17*G17 -> 59 | I17: vg_ch1fs01 | J17: 10:00
C18: pkfchapr2 | D18: =VLOOKUP($C$2:$C$171,가상화배치내역!$A$2:$B$335,2,FALSE) -> pkvex1010 | E18: VVR_vg_ch2fs01 | F18: 1 | G18: 59 | H18: =F18*G18 -> 59 | I18: vg_ch2fs01 | J18: 10:01
C19: pkfchapr3 | D19: =VLOOKUP($C$2:$C$171,가상화배치내역!$A$2:$B$335,2,FALSE) -> pkvex1014 | E19: VVR_vg_ch3fs01 | F19: 1 | G19: 59 | H19: =F19*G19 -> 59 | I19: vg_ch3fs01 | J19: 10:02
C20: pkfchapr1 | D20: =VLOOKUP($C$2:$C$171,가상화배치내역!$A$2:$B$335,2,FALSE) -> pkvex1006 | E20: VVR_vg_chcfs01 | F20: 1 | G20: 7.5 | H20: =F20*G20 -> 7.5 | I20: vg_chcfs01 | J20: 10:03
C21: pkfchapr2 | D21: =VLOOKUP($C$2:$C$171,가상화배치내역!$A$2:$B$335,2,FALSE) -> pkvex1010 | E21: VVR_vg_chcfs01 | F21: 1 | G21: 7.5 | H21: =F21*G21 -> 7.5 | I21: vg_chcfs01 | J21: 10:03
C22: pkfchapr3 | D22: =VLOOKUP($C$2:$C$171,가상화배치내역!$A$2:$B$335,2,FALSE) -> pkvex1014 | E22: VVR_vg_chcfs01 | F22: 1 | G22: 7.5 | H22: =F22*G22 -> 7.5 | I22: vg_chcfs01 | J22: 10:03
C23: S-DR-RDMP-LUN192-PKFCHAPR | D23: =VLOOKUP($C$2:$C$171,가상화배치내역!$A$2:$B$335,2,FALSE) -> #N/A | E23: RDMp | F23: 1 | G23: 1.5 | H23: =F23*G23 -> 1.5 | I23: RDMp | J23: 1F:00
A24: DR 파생 매칭 | B24: pkvex1003 pkvex1013 | C24: pkftrapr1 | D24: =VLOOKUP($C$2:$C$171,가상화배치내역!$A$2:$B$335,2,FALSE) -> pkvex1003 | E24: vg_tr1fs01 | F24: 1 | G24: 50 | H24: =F24*G24 -> 50 | I24: vg_me1fs01 | J24: 0.0027777778
C25: pkftrapr2 | D25: =VLOOKUP($C$2:$C$171,가상화배치내역!$A$2:$B$335,2,FALSE) -> pkvex1013 | E25: vg_tr2fs01 | F25: 1 | G25: 50 | H25: =F25*G25 -> 50 | I25: vg_me2fs01 | J25: 0.0034722222
C26: pkftrapr1 | D26: =VLOOKUP($C$2:$C$171,가상화배치내역!$A$2:$B$335,2,FALSE) -> pkvex1003 | E26: vg_trcfs01 | F26: 1 | G26: 90 | H26: =F26*G26 -> 90 | I26: vg_mecfs01 | J26: 0.0048611111
E27: vg_trcfs02 | F27: 1 | G27: 110 | H27: =F27*G27 -> 110 | I27: vg_mecfs03 | J27: 0.0055555556
E28: Lock Device | F28: 1 | G28: 0.2 | H28: =F28*G28 -> 0.2 | I28: Lock Device | J28: 0F:03
E29: Lock Device | F29: 1 | G29: 0.2 | H29: =F29*G29 -> 0.2 | I29: Lock Device | J29: 0F:04
E30: Lock Device | F30: 1 | G30: 0.2 | H30: =F30*G30 -> 0.2 | I30: Lock Device | J30: 0F:05
C31: pkftrapr2 | D31: =VLOOKUP($C$2:$C$171,가상화배치내역!$A$2:$B$335,2,FALSE) -> pkvex1013 | E31: vg_trcfs01 | F31: 1 | G31: 90 | H31: =F31*G31 -> 90 | I31: vg_mecfs01 | J31: 0.0048611111
E32: vg_trcfs02 | F32: 1 | G32: 110 | H32: =F32*G32 -> 110 | I32: vg_mecfs03 | J32: 0.0055555556
E33: Lock Device | F33: 1 | G33: 0.2 | H33: =F33*G33 -> 0.2 | I33: Lock Device | J33: 0F:03
E34: Lock Device | F34: 1 | G34: 0.2 | H34: =F34*G34 -> 0.2 | I34: Lock Device | J34: 0F:04
E35: Lock Device | F35: 1 | G35: 0.2 | H35: =F35*G35 -> 0.2 | I35: Lock Device | J35: 0F:05
C36: pkftrapr1 | D36: =VLOOKUP($C$2:$C$171,가상화배치내역!$A$2:$B$335,2,FALSE) -> pkvex1003 | E36: vg_tr1fs01 | F36: 1 | G36: 4.7 | H36: =F36*G36 -> 4.7 | I36: vg_me1fs01 | J36: 10:04
C37: pkftrapr2 | D37: =VLOOKUP($C$2:$C$171,가상화배치내역!$A$2:$B$335,2,FALSE) -> pkvex1013 | E37: vg_tr2fs01 | F37: 1 | G37: 4.7 | H37: =F37*G37 -> 4.7 | I37: vg_me2fs01 | J37: 10:05
C38: pkftrapr1 | D38: =VLOOKUP($C$2:$C$171,가상화배치내역!$A$2:$B$335,2,FALSE) -> pkvex1003 | E38: vg_trcfs01 | F38: 1 | G38: 9 | H38: =F38*G38 -> 9 | I38: vg_trcfs01 | J38: 10:07
E39: vg_trcfs02 | F39: 1 | G39: 10.2 | H39: =F39*G39 -> 10.2 | I39: vg_mecfs03 | J39: 10:08
C40: pkftrapr2 | D40: =VLOOKUP($C$2:$C$171,가상화배치내역!$A$2:$B$335,2,FALSE) -> pkvex1013 | E40: vg_trcfs01 | F40: 1 | G40: 9 | H40: =F40*G40 -> 9 | I40: vg_trcfs01 | J40: 10:07
...

Sheet 스토리지-가상화현황(정렬)
A1: 구분 | B1: HOSTNAME | C1: 가상화 호스트 | D1: 서버명(Guest) | E1: VG명 | F1: LUN수 | G1: Lun Size | H1: 할당량 | I1: LUN name | J1: LUN Address | K1: 사용 Port
A2: DR 파생 접속 | B2: pkvex1006 pkvex1010 pkvex1014 | C2: =VLOOKUP($D$2:$D$171,가상화배치내역!$A$2:$B$335,2,FALSE) -> pkvex1006 | D2: pkfchapr1 | E2: vg_ch1fs01 | F2: 1 | G2: 590 | H2: =F2*G2 -> 590 | I2: vg_ch1fs01 | J2: 0 | K2: 1A/2A/3A/4A/1C/2C/3C/4C
C3: =VLOOKUP($D$2:$D$171,가상화배치내역!$A$2:$B$335,2,FALSE) -> pkvex1010 | D3: pkfchapr2 | E3: vg_ch2fs01 | F3: 1 | G3: 590 | H3: =F3*G3 -> 590 | I3: vg_ch2fs01 | J3: 0.00069444444 | K3: 1A/2A/3A/4A/1C/2C/3C/4C
C4: =VLOOKUP($D$2:$D$171,가상화배치내역!$A$2:$B$335,2,FALSE) -> pkvex1014 | D4: pkfchapr3 | E4: vg_ch3fs01 | F4: 1 | G4: 590 | H4: =F4*G4 -> 590 | I4: vg_ch3fs01 | J4: 0.0013888889 | K4: 1A/2A/3A/4A/1C/2C/3C/4C
C5: =VLOOKUP($D$2:$D$171,가상화배치내역!$A$2:$B$335,2,FALSE) -> pkvex1006 | D5: pkfchapr1 | E5: vg_chcfs01 | F5: 1 | G5: 75 | H5: =F5*G5 -> 75 | I5: vg_chcfs01 | J5: 0.0020833333 | K5: 1A/2A/3A/4A/1C/2C/3C/4C
C6: =VLOOKUP($D$2:$D$171,가상화배치내역!$A$2:$B$335,2,FALSE) -> pkvex1006 | D6: pkfchapr1 | E6: Lock Device | F6: 1 | G6: 0.2 | H6: =F6*G6 -> 0.2 | I6: Lock Device | J6: 0F:00 | K6: 1A/2A/3A/4A/1C/2C/3C/4C
C7: =VLOOKUP($D$2:$D$171,가상화배치내역!$A$2:$B$335,2,FALSE) -> pkvex1006 | D7: pkfchapr1 | E7: Lock Device | F7: 1 | G7: 0.2 | H7: =F7*G7 -> 0.2 | I7: Lock Device | J7: 0F:01 | K7: 1A/2A/3A/4A/1C/2C/3C/4C
C8: =VLOOKUP($D$2:$D$171,가상화배치내역!$A$2:$B$335,2,FALSE) -> pkvex1006 | D8: pkfchapr1 | E8: Lock Device | F8: 1 | G8: 0.2 | H8: =F8*G8 -> 0.2 | I8: Lock Device | J8: 0F:02 | K8: 1A/2A/3A/4A/1C/2C/3C/4C
C9: =VLOOKUP($D$2:$D$171,가상화배치내역!$A$2:$B$335,2,FALSE) -> pkvex1010 | D9: pkfchapr2 | E9: vg_chcfs01 | F9: 1 | G9: 75 | H9: =F9*G9 -> 75 | I9: vg_chcfs01 | J9: 0.0020833333 | K9: 1A/2A/3A/4A/1C/2C/3C/4C
C10: pkvex1010 | D10: pkfchapr2 | E10: Lock Device | F10: 1 | G10: 0.2 | H10: =F10*G10 -> 0.2 | I10: Lock Device | J10: 0F:00 | K10: 1A/2A/3A/4A/1C/2C/3C/4C
C11: pkvex1010 | D11: pkfchapr2 | E11: Lock Device | F11: 1 | G11: 0.2 | H11: =F11*G11 -> 0.2 | I11: Lock Device | J11: 0F:01 | K11: 1A/2A/3A/4A/1C/2C/3C/4C
C12: pkvex1010 | D12: pkfchapr2 | E12: Lock Device | F12: 1 | G12: 0.2 | H12: =F12*G12 -> 0.2 | I12: Lock Device | J12: 0F:02 | K12: 1A/2A/3A/4A/1C/2C/3C/4C
C13: =VLOOKUP($D$2:$D$171,가상화배치내역!$A$2:$B$335,2,FALSE) -> pkvex1014 | D13: pkfchapr3 | E13: vg_chcfs01 | F13: 1 | G13: 75 | H13: =F13*G13 -> 75 | I13: vg_chcfs01 | J13: 0.0020833333 | K13: 1A/2A/3A/4A/1C/2C/3C/4C
C14: pkvex1014 | D14: pkfchapr3 | E14: Lock Device | F14: 1 | G14: 0.2 | H14: =F14*G14 -> 0.2 | I14: Lock Device | J14: 0F:00 | K14: 1A/2A/3A/4A/1C/2C/3C/4C
C15: pkvex1014 | D15: pkfchapr3 | E15: Lock Device | F15: 1 | G15: 0.2 | H15: =F15*G15 -> 0.2 | I15: Lock Device | J15: 0F:01 | K15: 1A/2A/3A/4A/1C/2C/3C/4C
C16: pkvex1014 | D16: pkfchapr3 | E16: Lock Device | F16: 1 | G16: 0.2 | H16: =F16*G16 -> 0.2 | I16: Lock Device | J16: 0F:02 | K16: 1A/2A/3A/4A/1C/2C/3C/4C
C17: =VLOOKUP($D$2:$D$171,가상화배치내역!$A$2:$B$335,2,FALSE) -> pkvex1006 | D17: pkfchapr1 | E17: VVR_vg_ch1fs01 | F17: 1 | G17: 59 | H17: =F17*G17 -> 59 | I17: vg_ch1fs01 | J17: 10:00 | K17: 1A/2A/3A/4A/1C/2C/3C/4C
C18: =VLOOKUP($D$2:$D$171,가상화배치내역!$A$2:$B$335,2,FALSE) -> pkvex1010 | D18: pkfchapr2 | E18: VVR_vg_ch2fs01 | F18: 1 | G18: 59 | H18: =F18*G18 -> 59 | I18: vg_ch2fs01 | J18: 10:01 | K18: 1A/2A/3A/4A/1C/2C/3C/4C
C19: =VLOOKUP($D$2:$D$171,가상화배치내역!$A$2:$B$335,2,FALSE) -> pkvex1014 | D19: pkfchapr3 | E19: VVR_vg_ch3fs01 | F19: 1 | G19: 59 | H19: =F19*G19 -> 59 | I19: vg_ch3fs01 | J19: 10:02 | K19: 1A/2A/3A/4A/1C/2C/3C/4C
C20: =VLOOKUP($D$2:$D$171,가상화배치내역!$A$2:$B$335,2,FALSE) -> pkvex1006 | D20: pkfchapr1 | E20: VVR_vg_chcfs01 | F20: 1 | G20: 7.5 | H20: =F20*G20 -> 7.5 | I20: vg_chcfs01 | J20: 10:03 | K20: 1A/2A/3A/4A/1C/2C/3C/4C
C21: =VLOOKUP($D$2:$D$171,가상화배치내역!$A$2:$B$335,2,FALSE) -> pkvex1010 | D21: pkfchapr2 | E21: VVR_vg_chcfs01 | F21: 1 | G21: 7.5 | H21: =F21*G21 -> 7.5 | I21: vg_chcfs01 | J21: 10:03 | K21: 1A/2A/3A/4A/1C/2C/3C/4C
C22: =VLOOKUP($D$2:$D$171,가상화배치내역!$A$2:$B$335,2,FALSE) -> pkvex1014 | D22: pkfchapr3 | E22: VVR_vg_chcfs01 | F22: 1 | G22: 7.5 | H22: =F22*G22 -> 7.5 | I22: vg_chcfs01 | J22: 10:03 | K22: 1A/2A/3A/4A/1C/2C/3C/4C
C23: =VLOOKUP($D$2:$D$171,가상화배치내역!$A$2:$B$335,2,FALSE) -> #N/A | D23: S-DR-RDMP-LUN192-PKFCHAPR | E23: RDMp | F23: 1 | G23: 1.5 | H23: =F23*G23 -> 1.5 | I23: RDMp | J23: 1F:00 | K23: 1A/2A/3A/4A/1C/2C/3C/4C
A24: DR 파생 매칭 | B24: pkvex1003 pkvex1013 | C24: =VLOOKUP($D$2:$D$171,가상화배치내역!$A$2:$B$335,2,FALSE) -> pkvex1003 | D24: pkftrapr1 | E24: vg_tr1fs01 | F24: 1 | G24: 50 | H24: =F24*G24 -> 50 | I24: vg_me1fs01 | J24: 0.0027777778 | K24: 1A/2A/3A/4A/1C/2C/3C/4C
C25: =VLOOKUP($D$2:$D$171,가상화배치내역!$A$2:$B$335,2,FALSE) -> pkvex1013 | D25: pkftrapr2 | E25: vg_tr2fs01 | F25: 1 | G25: 50 | H25: =F25*G25 -> 50 | I25: vg_me2fs01 | J25: 0.0034722222 | K25: 1A/2A/3A/4A/1C/2C/3C/4C
C26: =VLOOKUP($D$2:$D$171,가상화배치내역!$A$2:$B$335,2,FALSE) -> pkvex1003 | D26: pkftrapr1 | E26: vg_trcfs01 | F26: 1 | G26: 90 | H26: =F26*G26 -> 90 | I26: vg_mecfs01 | J26: 0.0048611111 | K26: 1A/2A/3A/4A/1C/2C/3C/4C
C27: pkvex1003 | D27: pkftrapr1 | E27: vg_trcfs02 | F27: 1 | G27: 110 | H27: =F27*G27 -> 110 | I27: vg_mecfs03 | J27: 0.0055555556 | K27: 1A/2A/3A/4A/1C/2C/3C/4C
C28: pkvex1003 | D28: pkftrapr1 | E28: Lock Device | F28: 1 | G28: 0.2 | H28: =F28*G28 -> 0.2 | I28: Lock Device | J28: 0F:03 | K28: 1A/2A/3A/4A/1C/2C/3C/4C
C29: pkvex1003 | D29: pkftrapr1 | E29: Lock Device | F29: 1 | G29: 0.2 | H29: =F29*G29 -> 0.2 | I29: Lock Device | J29: 0F:04 | K29: 1A/2A/3A/4A/1C/2C/3C/4C
C30: pkvex1003 | D30: pkftrapr1 | E30: Lock Device | F30: 1 | G30: 0.2 | H30: =F30*G30 -> 0.2 | I30: Lock Device | J30: 0F:05 | K30: 1A/2A/3A/4A/1C/2C/3C/4C
C31: =VLOOKUP($D$2:$D$171,가상화배치내역!$A$2:$B$335,2,FALSE) -> pkvex1013 | D31: pkftrapr2 | E31: vg_trcfs01 | F31: 1 | G31: 90 | H31: =F31*G31 -> 90 | I31: vg_mecfs01 | J31: 0.0048611111 | K31: 1A/2A/3A/4A/1C/2C/3C/4C
C32: pkvex1013 | D32: pkftrapr2 | E32: vg_trcfs02 | F32: 1 | G32: 110 | H32: =F32*G32 -> 110 | I32: vg_mecfs03 | J32: 0.0055555556 | K32: 1A/2A/3A/4A/1C/2C/3C/4C
C33: pkvex1013 | D33: pkftrapr2 | E33: Lock Device | F33: 1 | G33: 0.2 | H33: =F33*G33 -> 0.2 | I33: Lock Device | J33: 0F:03 | K33: 1A/2A/3A/4A/1C/2C/3C/4C
C34: pkvex1013 | D34: pkftrapr2 | E34: Lock Device | F34: 1 | G34: 0.2 | H34: =F34*G34 -> 0.2 | I34: Lock Device | J34: 0F:04 | K34: 1A/2A/3A/4A/1C/2C/3C/4C
C35: pkvex1013 | D35: pkftrapr2 | E35: Lock Device | F35: 1 | G35: 0.2 | H35: =F35*G35 -> 0.2 | I35: Lock Device | J35: 0F:05 | K35: 1A/2A/3A/4A/1C/2C/3C/4C
C36: =VLOOKUP($D$2:$D$171,가상화배치내역!$A$2:$B$335,2,FALSE) -> pkvex1003 | D36: pkftrapr1 | E36: vg_tr1fs01 | F36: 1 | G36: 4.7 | H36: =F36*G36 -> 4.7 | I36: vg_me1fs01 | J36: 10:04 | K36: 1A/2A/3A/4A/1C/2C/3C/4C
C37: =VLOOKUP($D$2:$D$171,가상화배치내역!$A$2:$B$335,2,FALSE) -> pkvex1013 | D37: pkftrapr2 | E37: vg_tr2fs01 | F37: 1 | G37: 4.7 | H37: =F37*G37 -> 4.7 | I37: vg_me2fs01 | J37: 10:05 | K37: 1A/2A/3A/4A/1C/2C/3C/4C
C38: =VLOOKUP($D$2:$D$171,가상화배치내역!$A$2:$B$335,2,FALSE) -> pkvex1003 | D38: pkftrapr1 | E38: vg_trcfs01 | F38: 1 | G38: 9 | H38: =F38*G38 -> 9 | I38: vg_trcfs01 | J38: 10:07 | K38: 1A/2A/3A/4A/1C/2C/3C/4C
C39: pkvex1003 | D39: pkftrapr1 | E39: vg_trcfs02 | F39: 1 | G39: 10.2 | H39: =F39*G39 -> 10.2 | I39: vg_mecfs03 | J39: 10:08 | K39: 1A/2A/3A/4A/1C/2C/3C/4C
C40: =VLOOKUP($D$2:$D$171,가상화배치내역!$A$2:$B$335,2,FALSE) -> pkvex1013 | D40: pkftrapr2 | E40: vg_trcfs01 | F40: 1 | G40: 9 | H40: =F40*G40 -> 9 | I40: vg_trcfs01 | J40: 10:07 | K40: 1A/2A/3A/4A/1C/2C/3C/4C
...

Sheet 스토리지-가상화현황(정렬) (2)
A1: 가상화 호스트 | B1: 가상화 호스트 | C1: 서버명(Guest) | D1: VG명 | E1: LUN수 | F1: Lun Size | G1: 할당량 | H1: LUN name | I1: LUN Address | J1: 사용 Port
A2: =VLOOKUP($C$2:$C$171,가상화배치내역!$A$2:$B$335,2,FALSE) -> #N/A | B2: #N/A | C2: - | E2: 1 | F2: 1024 | G2: =E2*F2 -> 1024 | I2: 1F:0A | J2: 1D/2D
A3: =VLOOKUP($C$2:$C$171,가상화배치내역!$A$2:$B$335,2,FALSE) -> pkvex1006 | B3: pkvex1006 | C3: pkfchapr1 | D3: vg_ch1fs01 | E3: 1 | F3: 590 | G3: =E3*F3 -> 590 | H3: vg_ch1fs01 | I3: 0 | J3: 1A/2A/3A/4A/1C/2C/3C/4C
A4: =VLOOKUP($C$2:$C$171,가상화배치내역!$A$2:$B$335,2,FALSE) -> pkvex1006 | B4: pkvex1006 | C4: pkfchapr1 | D4: vg_chcfs01 | E4: 1 | F4: 75 | G4: =E4*F4 -> 75 | H4: vg_chcfs01 | I4: 0.0020833333 | J4: 1A/2A/3A/4A/1C/2C/3C/4C
A5: =VLOOKUP($C$2:$C$171,가상화배치내역!$A$2:$B$335,2,FALSE) -> pkvex1006 | B5: pkvex1006 | C5: pkfchapr1 | D5: Lock Device | E5: 1 | F5: 0.2 | G5: =E5*F5 -> 0.2 | H5: Lock Device | I5: 0F:00 | J5: 1A/2A/3A/4A/1C/2C/3C/4C
A6: =VLOOKUP($C$2:$C$171,가상화배치내역!$A$2:$B$335,2,FALSE) -> pkvex1006 | B6: pkvex1006 | C6: pkfchapr1 | D6: Lock Device | E6: 1 | F6: 0.2 | G6: =E6*F6 -> 0.2 | H6: Lock Device | I6: 0F:01 | J6: 1A/2A/3A/4A/1C/2C/3C/4C
A7: =VLOOKUP($C$2:$C$171,가상화배치내역!$A$2:$B$335,2,FALSE) -> pkvex1006 | B7: pkvex1006 | C7: pkfchapr1 | D7: Lock Device | E7: 1 | F7: 0.2 | G7: =E7*F7 -> 0.2 | H7: Lock Device | I7: 0F:02 | J7: 1A/2A/3A/4A/1C/2C/3C/4C
A8: =VLOOKUP($C$2:$C$171,가상화배치내역!$A$2:$B$335,2,FALSE) -> pkvex1006 | B8: pkvex1006 | C8: pkfchapr1 | D8: VVR_vg_ch1fs01 | E8: 1 | F8: 59 | G8: =E8*F8 -> 59 | H8: vg_ch1fs01 | I8: 10:00 | J8: 1A/2A/3A/4A/1C/2C/3C/4C
A9: =VLOOKUP($C$2:$C$171,가상화배치내역!$A$2:$B$335,2,FALSE) -> pkvex1006 | B9: pkvex1006 | C9: pkfchapr1 | D9: VVR_vg_chcfs01 | E9: 1 | F9: 7.5 | G9: =E9*F9 -> 7.5 | H9: vg_chcfs01 | I9: 10:03 | J9: 1A/2A/3A/4A/1C/2C/3C/4C
A10: pkvex1010 | B10: pkvex1010 | C10: pkfchapr2 | D10: vg_ch2fs01 | E10: 1 | F10: 590 | G10: =E10*F10 -> 590 | H10: vg_ch2fs01 | I10: 0.00069444444 | J10: 1A/2A/3A/4A/1C/2C/3C/4C
A11: pkvex1010 | B11: pkvex1010 | C11: pkfchapr2 | D11: vg_chcfs01 | E11: 1 | F11: 75 | G11: =E11*F11 -> 75 | H11: vg_chcfs01 | I11: 0.0020833333 | J11: 1A/2A/3A/4A/1C/2C/3C/4C
A12: pkvex1010 | B12: pkvex1010 | C12: pkfchapr2 | D12: Lock Device | E12: 1 | F12: 0.2 | G12: =E12*F12 -> 0.2 | H12: Lock Device | I12: 0F:00 | J12: 1A/2A/3A/4A/1C/2C/3C/4C
A13: =VLOOKUP($C$2:$C$171,가상화배치내역!$A$2:$B$335,2,FALSE) -> pkvex1010 | B13: pkvex1010 | C13: pkfchapr2 | D13: Lock Device | E13: 1 | F13: 0.2 | G13: =E13*F13 -> 0.2 | H13: Lock Device | I13: 0F:01 | J13: 1A/2A/3A/4A/1C/2C/3C/4C
A14: pkvex1014 | B14: pkvex1010 | C14: pkfchapr2 | D14: Lock Device | E14: 1 | F14: 0.2 | G14: =E14*F14 -> 0.2 | H14: Lock Device | I14: 0F:02 | J14: 1A/2A/3A/4A/1C/2C/3C/4C
A15: pkvex1014 | B15: pkvex1010 | C15: pkfchapr2 | D15: VVR_vg_ch2fs01 | E15: 1 | F15: 59 | G15: =E15*F15 -> 59 | H15: vg_ch2fs01 | I15: 10:01 | J15: 1A/2A/3A/4A/1C/2C/3C/4C
A16: pkvex1014 | B16: pkvex1010 | C16: pkfchapr2 | D16: VVR_vg_chcfs01 | E16: 1 | F16: 7.5 | G16: =E16*F16 -> 7.5 | H16: vg_chcfs01 | I16: 10:03 | J16: 1A/2A/3A/4A/1C/2C/3C/4C
A17: =VLOOKUP($C$2:$C$171,가상화배치내역!$A$2:$B$335,2,FALSE) -> pkvex1014 | B17: pkvex1014 | C17: pkfchapr3 | D17: vg_ch3fs01 | E17: 1 | F17: 590 | G17: =E17*F17 -> 590 | H17: vg_ch3fs01 | I17: 0.0013888889 | J17: 1A/2A/3A/4A/1C/2C/3C/4C
A18: =VLOOKUP($C$2:$C$171,가상화배치내역!$A$2:$B$335,2,FALSE) -> pkvex1014 | B18: pkvex1014 | C18: pkfchapr3 | D18: vg_chcfs01 | E18: 1 | F18: 75 | G18: =E18*F18 -> 75 | H18: vg_chcfs01 | I18: 0.0020833333 | J18: 1A/2A/3A/4A/1C/2C/3C/4C
A19: =VLOOKUP($C$2:$C$171,가상화배치내역!$A$2:$B$335,2,FALSE) -> pkvex1014 | B19: pkvex1014 | C19: pkfchapr3 | D19: Lock Device | E19: 1 | F19: 0.2 | G19: =E19*F19 -> 0.2 | H19: Lock Device | I19: 0F:00 | J19: 1A/2A/3A/4A/1C/2C/3C/4C
A20: =VLOOKUP($C$2:$C$171,가상화배치내역!$A$2:$B$335,2,FALSE) -> pkvex1014 | B20: pkvex1014 | C20: pkfchapr3 | D20: Lock Device | E20: 1 | F20: 0.2 | G20: =E20*F20 -> 0.2 | H20: Lock Device | I20: 0F:01 | J20: 1A/2A/3A/4A/1C/2C/3C/4C
A21: =VLOOKUP($C$2:$C$171,가상화배치내역!$A$2:$B$335,2,FALSE) -> pkvex1014 | B21: pkvex1014 | C21: pkfchapr3 | D21: Lock Device | E21: 1 | F21: 0.2 | G21: =E21*F21 -> 0.2 | H21: Lock Device | I21: 0F:02 | J21: 1A/2A/3A/4A/1C/2C/3C/4C
A22: =VLOOKUP($C$2:$C$171,가상화배치내역!$A$2:$B$335,2,FALSE) -> pkvex1014 | B22: pkvex1014 | C22: pkfchapr3 | D22: VVR_vg_ch3fs01 | E22: 1 | F22: 59 | G22: =E22*F22 -> 59 | H22: vg_ch3fs01 | I22: 10:02 | J22: 1A/2A/3A/4A/1C/2C/3C/4C
A23: =VLOOKUP($C$2:$C$171,가상화배치내역!$A$2:$B$335,2,FALSE) -> pkvex1014 | B23: pkvex1014 | C23: pkfchapr3 | D23: VVR_vg_chcfs01 | E23: 1 | F23: 7.5 | G23: =E23*F23 -> 7.5 | H23: vg_chcfs01 | I23: 10:03 | J23: 1A/2A/3A/4A/1C/2C/3C/4C
A24: =VLOOKUP($C$2:$C$171,가상화배치내역!$A$2:$B$335,2,FALSE) -> pkvex1003 | B24: pkvex1003 | C24: pkftrapr1 | D24: vg_tr1fs01 | E24: 1 | F24: 50 | G24: =E24*F24 -> 50 | H24: vg_me1fs01 | I24: 0.0027777778 | J24: 1A/2A/3A/4A/1C/2C/3C/4C
A25: =VLOOKUP($C$2:$C$171,가상화배치내역!$A$2:$B$335,2,FALSE) -> pkvex1003 | B25: pkvex1003 | C25: pkftrapr1 | D25: vg_trcfs01 | E25: 1 | F25: 90 | G25: =E25*F25 -> 90 | H25: vg_mecfs01 | I25: 0.0048611111 | J25: 1A/2A/3A/4A/1C/2C/3C/4C
A26: =VLOOKUP($C$2:$C$171,가상화배치내역!$A$2:$B$335,2,FALSE) -> pkvex1003 | B26: pkvex1003 | C26: pkftrapr1 | D26: vg_trcfs02 | E26: 1 | F26: 110 | G26: =E26*F26 -> 110 | H26: vg_mecfs03 | I26: 0.0055555556 | J26: 1A/2A/3A/4A/1C/2C/3C/4C
A27: pkvex1003 | B27: pkvex1003 | C27: pkftrapr1 | D27: Lock Device | E27: 1 | F27: 0.2 | G27: =E27*F27 -> 0.2 | H27: Lock Device | I27: 0F:03 | J27: 1A/2A/3A/4A/1C/2C/3C/4C
A28: pkvex1003 | B28: pkvex1003 | C28: pkftrapr1 | D28: Lock Device | E28: 1 | F28: 0.2 | G28: =E28*F28 -> 0.2 | H28: Lock Device | I28: 0F:04 | J28: 1A/2A/3A/4A/1C/2C/3C/4C
A29: pkvex1003 | B29: pkvex1003 | C29: pkftrapr1 | D29: Lock Device | E29: 1 | F29: 0.2 | G29: =E29*F29 -> 0.2 | H29: Lock Device | I29: 0F:05 | J29: 1A/2A/3A/4A/1C/2C/3C/4C
A30: pkvex1003 | B30: pkvex1003 | C30: pkftrapr1 | D30: vg_tr1fs01 | E30: 1 | F30: 4.7 | G30: =E30*F30 -> 4.7 | H30: vg_me1fs01 | I30: 10:04 | J30: 1A/2A/3A/4A/1C/2C/3C/4C
A31: =VLOOKUP($C$2:$C$171,가상화배치내역!$A$2:$B$335,2,FALSE) -> pkvex1003 | B31: pkvex1003 | C31: pkftrapr1 | D31: vg_trcfs01 | E31: 1 | F31: 9 | G31: =E31*F31 -> 9 | H31: vg_trcfs01 | I31: 10:07 | J31: 1A/2A/3A/4A/1C/2C/3C/4C
A32: pkvex1013 | B32: pkvex1003 | C32: pkftrapr1 | D32: vg_trcfs02 | E32: 1 | F32: 10.2 | G32: =E32*F32 -> 10.2 | H32: vg_mecfs03 | I32: 10:08 | J32: 1A/2A/3A/4A/1C/2C/3C/4C
A33: pkvex1013 | B33: pkvex1013 | C33: pkftrapr2 | D33: vg_tr2fs01 | E33: 1 | F33: 50 | G33: =E33*F33 -> 50 | H33: vg_me2fs01 | I33: 0.0034722222 | J33: 1A/2A/3A/4A/1C/2C/3C/4C
A34: pkvex1013 | B34: pkvex1013 | C34: pkftrapr2 | D34: vg_trcfs01 | E34: 1 | F34: 90 | G34: =E34*F34 -> 90 | H34: vg_mecfs01 | I34: 0.0048611111 | J34: 1A/2A/3A/4A/1C/2C/3C/4C
A35: pkvex1013 | B35: pkvex1013 | C35: pkftrapr2 | D35: vg_trcfs02 | E35: 1 | F35: 110 | G35: =E35*F35 -> 110 | H35: vg_mecfs03 | I35: 0.0055555556 | J35: 1A/2A/3A/4A/1C/2C/3C/4C
A36: =VLOOKUP($C$2:$C$171,가상화배치내역!$A$2:$B$335,2,FALSE) -> pkvex1013 | B36: pkvex1013 | C36: pkftrapr2 | D36: Lock Device | E36: 1 | F36: 0.2 | G36: =E36*F36 -> 0.2 | H36: Lock Device | I36: 0F:03 | J36: 1A/2A/3A/4A/1C/2C/3C/4C
A37: =VLOOKUP($C$2:$C$171,가상화배치내역!$A$2:$B$335,2,FALSE) -> pkvex1013 | B37: pkvex1013 | C37: pkftrapr2 | D37: Lock Device | E37: 1 | F37: 0.2 | G37: =E37*F37 -> 0.2 | H37: Lock Device | I37: 0F:04 | J37: 1A/2A/3A/4A/1C/2C/3C/4C
A38: =VLOOKUP($C$2:$C$171,가상화배치내역!$A$2:$B$335,2,FALSE) -> pkvex1013 | B38: pkvex1013 | C38: pkftrapr2 | D38: Lock Device | E38: 1 | F38: 0.2 | G38: =E38*F38 -> 0.2 | H38: Lock Device | I38: 0F:05 | J38: 1A/2A/3A/4A/1C/2C/3C/4C
A39: pkvex1003 | B39: pkvex1013 | C39: pkftrapr2 | D39: vg_tr2fs01 | E39: 1 | F39: 4.7 | G39: =E39*F39 -> 4.7 | H39: vg_me2fs01 | I39: 10:05 | J39: 1A/2A/3A/4A/1C/2C/3C/4C
A40: =VLOOKUP($C$2:$C$171,가상화배치내역!$A$2:$B$335,2,FALSE) -> pkvex1013 | B40: pkvex1013 | C40: pkftrapr2 | D40: vg_trcfs01 | E40: 1 | F40: 9 | G40: =E40*F40 -> 9 | H40: vg_trcfs01 | I40: 10:07 | J40: 1A/2A/3A/4A/1C/2C/3C/4C
...

Sheet 스토리지_가상화현황(정렬완료)
B1: 가상화 호스트 | C1: 가상화호스트 LUN정보 | E1: Guest LUN정보 | H1: 서버명(Guest) | I1: VG명 | J1: LUN수 | K1: Lun Size | L1: 할당량 | M1: LUN name | N1: LUN ADDR | O1: 사용Port
A2: 가상화 호스트 | C2: DataStore NO | D2: Size(GB) | E2: LUN NO | F2: Size(GB) | G2: Location
A3: =VLOOKUP($H$3:$H$172,가상화배치내역!$A$2:$B$335,2,FALSE) -> #N/A | B3: #N/A | H3: - | J3: 1 | K3: 1024 | L3: =J3*K3 -> 1024 | N3: 1F:0A | O3: 1D/2D
A4: =VLOOKUP($H$3:$H$172,가상화배치내역!$A$2:$B$335,2,FALSE) -> pkvex1006 | B4: pkvex1006 | H4: pkfchapr1 | I4: vg_ch1fs01 | J4: 1 | K4: 590 | L4: =J4*K4 -> 590 | M4: vg_ch1fs01 | N4: 0 | O4: 1A/2A/3A/4A/1C/2C/3C/4C
A5: =VLOOKUP($H$3:$H$172,가상화배치내역!$A$2:$B$335,2,FALSE) -> #N/A | I5: vg_chcfs01 | J5: 1 | K5: 75 | L5: =J5*K5 -> 75 | M5: vg_chcfs01 | N5: 0.0020833333 | O5: 1A/2A/3A/4A/1C/2C/3C/4C
A6: =VLOOKUP($H$3:$H$172,가상화배치내역!$A$2:$B$335,2,FALSE) -> #N/A | I6: Lock Device | J6: 1 | K6: 0.2 | L6: =J6*K6 -> 0.2 | M6: Lock Device | N6: 0F:00 | O6: 1A/2A/3A/4A/1C/2C/3C/4C
A7: =VLOOKUP($H$3:$H$172,가상화배치내역!$A$2:$B$335,2,FALSE) -> #N/A | I7: Lock Device | J7: 1 | K7: 0.2 | L7: =J7*K7 -> 0.2 | M7: Lock Device | N7: 0F:01 | O7: 1A/2A/3A/4A/1C/2C/3C/4C
A8: =VLOOKUP($H$3:$H$172,가상화배치내역!$A$2:$B$335,2,FALSE) -> #N/A | I8: Lock Device | J8: 1 | K8: 0.2 | L8: =J8*K8 -> 0.2 | M8: Lock Device | N8: 0F:02 | O8: 1A/2A/3A/4A/1C/2C/3C/4C
A9: =VLOOKUP($H$3:$H$172,가상화배치내역!$A$2:$B$335,2,FALSE) -> #N/A | I9: VVR_vg_ch1fs01 | J9: 1 | K9: 59 | L9: =J9*K9 -> 59 | M9: vg_ch1fs01 | N9: 10:00 | O9: 1A/2A/3A/4A/1C/2C/3C/4C
A10: =VLOOKUP($H$3:$H$172,가상화배치내역!$A$2:$B$335,2,FALSE) -> #N/A | I10: VVR_vg_chcfs01 | J10: 1 | K10: 7.5 | L10: =J10*K10 -> 7.5 | M10: vg_chcfs01 | N10: 10:03 | O10: 1A/2A/3A/4A/1C/2C/3C/4C
A11: pkvex1010 | B11: pkvex1010 | H11: pkfchapr2 | I11: vg_ch2fs01 | J11: 1 | K11: 590 | L11: =J11*K11 -> 590 | M11: vg_ch2fs01 | N11: 0.00069444444 | O11: 1A/2A/3A/4A/1C/2C/3C/4C
A12: pkvex1010 | I12: vg_chcfs01 | J12: 1 | K12: 75 | L12: =J12*K12 -> 75 | M12: vg_chcfs01 | N12: 0.0020833333 | O12: 1A/2A/3A/4A/1C/2C/3C/4C
A13: pkvex1010 | I13: Lock Device | J13: 1 | K13: 0.2 | L13: =J13*K13 -> 0.2 | M13: Lock Device | N13: 0F:00 | O13: 1A/2A/3A/4A/1C/2C/3C/4C
A14: =VLOOKUP($H$3:$H$172,가상화배치내역!$A$2:$B$335,2,FALSE) -> #N/A | I14: Lock Device | J14: 1 | K14: 0.2 | L14: =J14*K14 -> 0.2 | M14: Lock Device | N14: 0F:01 | O14: 1A/2A/3A/4A/1C/2C/3C/4C
A15: pkvex1014 | I15: Lock Device | J15: 1 | K15: 0.2 | L15: =J15*K15 -> 0.2 | M15: Lock Device | N15: 0F:02 | O15: 1A/2A/3A/4A/1C/2C/3C/4C
A16: pkvex1014 | I16: VVR_vg_ch2fs01 | J16: 1 | K16: 59 | L16: =J16*K16 -> 59 | M16: vg_ch2fs01 | N16: 10:01 | O16: 1A/2A/3A/4A/1C/2C/3C/4C
A17: pkvex1014 | I17: VVR_vg_chcfs01 | J17: 1 | K17: 7.5 | L17: =J17*K17 -> 7.5 | M17: vg_chcfs01 | N17: 10:03 | O17: 1A/2A/3A/4A/1C/2C/3C/4C
A18: =VLOOKUP($H$3:$H$172,가상화배치내역!$A$2:$B$335,2,FALSE) -> pkvex1014 | B18: pkvex1014 | H18: pkfchapr3 | I18: vg_ch3fs01 | J18: 1 | K18: 590 | L18: =J18*K18 -> 590 | M18: vg_ch3fs01 | N18: 0.0013888889 | O18: 1A/2A/3A/4A/1C/2C/3C/4C
A19: =VLOOKUP($H$3:$H$172,가상화배치내역!$A$2:$B$335,2,FALSE) -> #N/A | I19: vg_chcfs01 | J19: 1 | K19: 75 | L19: =J19*K19 -> 75 | M19: vg_chcfs01 | N19: 0.0020833333 | O19: 1A/2A/3A/4A/1C/2C/3C/4C
A20: =VLOOKUP($H$3:$H$172,가상화배치내역!$A$2:$B$335,2,FALSE) -> #N/A | I20: Lock Device | J20: 1 | K20: 0.2 | L20: =J20*K20 -> 0.2 | M20: Lock Device | N20: 0F:00 | O20: 1A/2A/3A/4A/1C/2C/3C/4C
A21: =VLOOKUP($H$3:$H$172,가상화배치내역!$A$2:$B$335,2,FALSE) -> #N/A | I21: Lock Device | J21: 1 | K21: 0.2 | L21: =J21*K21 -> 0.2 | M21: Lock Device | N21: 0F:01 | O21: 1A/2A/3A/4A/1C/2C/3C/4C
A22: =VLOOKUP($H$3:$H$172,가상화배치내역!$A$2:$B$335,2,FALSE) -> #N/A | I22: Lock Device | J22: 1 | K22: 0.2 | L22: =J22*K22 -> 0.2 | M22: Lock Device | N22: 0F:02 | O22: 1A/2A/3A/4A/1C/2C/3C/4C
A23: =VLOOKUP($H$3:$H$172,가상화배치내역!$A$2:$B$335,2,FALSE) -> #N/A | I23: VVR_vg_ch3fs01 | J23: 1 | K23: 59 | L23: =J23*K23 -> 59 | M23: vg_ch3fs01 | N23: 10:02 | O23: 1A/2A/3A/4A/1C/2C/3C/4C
A24: =VLOOKUP($H$3:$H$172,가상화배치내역!$A$2:$B$335,2,FALSE) -> #N/A | I24: VVR_vg_chcfs01 | J24: 1 | K24: 7.5 | L24: =J24*K24 -> 7.5 | M24: vg_chcfs01 | N24: 10:03 | O24: 1A/2A/3A/4A/1C/2C/3C/4C
A25: =VLOOKUP($H$3:$H$172,가상화배치내역!$A$2:$B$335,2,FALSE) -> pkvex1003 | B25: pkvex1003 | H25: pkftrapr1 | I25: vg_tr1fs01 | J25: 1 | K25: 50 | L25: =J25*K25 -> 50 | M25: vg_me1fs01 | N25: 0.0027777778 | O25: 1A/2A/3A/4A/1C/2C/3C/4C
A26: =VLOOKUP($H$3:$H$172,가상화배치내역!$A$2:$B$335,2,FALSE) -> #N/A | I26: vg_trcfs01 | J26: 1 | K26: 90 | L26: =J26*K26 -> 90 | M26: vg_mecfs01 | N26: 0.0048611111 | O26: 1A/2A/3A/4A/1C/2C/3C/4C
A27: =VLOOKUP($H$3:$H$172,가상화배치내역!$A$2:$B$335,2,FALSE) -> #N/A | I27: vg_trcfs02 | J27: 1 | K27: 110 | L27: =J27*K27 -> 110 | M27: vg_mecfs03 | N27: 0.0055555556 | O27: 1A/2A/3A/4A/1C/2C/3C/4C
A28: pkvex1003 | I28: Lock Device | J28: 1 | K28: 0.2 | L28: =J28*K28 -> 0.2 | M28: Lock Device | N28: 0F:03 | O28: 1A/2A/3A/4A/1C/2C/3C/4C
A29: pkvex1003 | I29: Lock Device | J29: 1 | K29: 0.2 | L29: =J29*K29 -> 0.2 | M29: Lock Device | N29: 0F:04 | O29: 1A/2A/3A/4A/1C/2C/3C/4C
A30: pkvex1003 | I30: Lock Device | J30: 1 | K30: 0.2 | L30: =J30*K30 -> 0.2 | M30: Lock Device | N30: 0F:05 | O30: 1A/2A/3A/4A/1C/2C/3C/4C
A31: pkvex1003 | I31: vg_tr1fs01 | J31: 1 | K31: 4.7 | L31: =J31*K31 -> 4.7 | M31: vg_me1fs01 | N31: 10:04 | O31: 1A/2A/3A/4A/1C/2C/3C/4C
A32: =VLOOKUP($H$3:$H$172,가상화배치내역!$A$2:$B$335,2,FALSE) -> #N/A | I32: vg_trcfs01 | J32: 1 | K32: 9 | L32: =J32*K32 -> 9 | M32: vg_trcfs01 | N32: 10:07 | O32: 1A/2A/3A/4A/1C/2C/3C/4C
A33: pkvex1013 | I33: vg_trcfs02 | J33: 1 | K33: 10.2 | L33: =J33*K33 -> 10.2 | M33: vg_mecfs03 | N33: 10:08 | O33: 1A/2A/3A/4A/1C/2C/3C/4C
A34: pkvex1013 | B34: pkvex1013 | H34: pkftrapr2 | I34: vg_tr2fs01 | J34: 1 | K34: 50 | L34: =J34*K34 -> 50 | M34: vg_me2fs01 | N34: 0.0034722222 | O34: 1A/2A/3A/4A/1C/2C/3C/4C
A35: pkvex1013 | I35: vg_trcfs01 | J35: 1 | K35: 90 | L35: =J35*K35 -> 90 | M35: vg_mecfs01 | N35: 0.0048611111 | O35: 1A/2A/3A/4A/1C/2C/3C/4C
A36: pkvex1013 | I36: vg_trcfs02 | J36: 1 | K36: 110 | L36: =J36*K36 -> 110 | M36: vg_mecfs03 | N36: 0.0055555556 | O36: 1A/2A/3A/4A/1C/2C/3C/4C
A37: =VLOOKUP($H$3:$H$172,가상화배치내역!$A$2:$B$335,2,FALSE) -> #N/A | I37: Lock Device | J37: 1 | K37: 0.2 | L37: =J37*K37 -> 0.2 | M37: Lock Device | N37: 0F:03 | O37: 1A/2A/3A/4A/1C/2C/3C/4C
A38: =VLOOKUP($H$3:$H$172,가상화배치내역!$A$2:$B$335,2,FALSE) -> #N/A | I38: Lock Device | J38: 1 | K38: 0.2 | L38: =J38*K38 -> 0.2 | M38: Lock Device | N38: 0F:04 | O38: 1A/2A/3A/4A/1C/2C/3C/4C
A39: =VLOOKUP($H$3:$H$172,가상화배치내역!$A$2:$B$335,2,FALSE) -> #N/A | I39: Lock Device | J39: 1 | K39: 0.2 | L39: =J39*K39 -> 0.2 | M39: Lock Device | N39: 0F:05 | O39: 1A/2A/3A/4A/1C/2C/3C/4C
A40: pkvex1003 | I40: vg_tr2fs01 | J40: 1 | K40: 4.7 | L40: =J40*K40 -> 4.7 | M40: vg_me2fs01 | N40: 10:05 | O40: 1A/2A/3A/4A/1C/2C/3C/4C
...

Sheet naa정보-입력
B1: 예
B2: =RIGHT(C2,4) -> 004c | C2: naa.60060e8016622100000162210000004c | D2: <<<=== C 열에 신규 g600용 naa 값을 복사/붙여넣기 B열은 자동으로 채워짐(손대지 말것)
B3: lun_id | C3: naa값(전체 lun갯수는 346개)
A4: 1 | B4: =RIGHT(C4,4) -> 004c | C4: naa.60060e8016622100000162210000004c
A5: 2 | B5: =RIGHT(C5,4)
A6: 3 | B6: =RIGHT(C6,4)
A7: 4 | B7: =RIGHT(C7,4)
A8: 5 | B8: =RIGHT(C8,4)
A9: 6 | B9: =RIGHT(C9,4)
A10: 7 | B10: =RIGHT(C10,4)
A11: 8 | B11: =RIGHT(C11,4)
A12: 9 | B12: =RIGHT(C12,4)
A13: 10 | B13: =RIGHT(C13,4)
A14: 11 | B14: =RIGHT(C14,4)
A15: 12 | B15: =RIGHT(C15,4)
A16: 13 | B16: =RIGHT(C16,4)
... A349: 346 | B349: =RIGHT(C349,4)

Sheet 부산 DR_VMware
A1: 부산 가상화 DR 구성 현황 (2018.09.10)
A3: VM Guest | V3: OS | AA3: Volum Manager (Veritas) | AG3: 스토리지 | AN3: vmkfstools -z /vmfs/devices/disks/
A4: System | E4: Data Store Mapping | M4: LUN info | Q4: TO-BE Data Store Mapping | V4: Systsem | W4: Disk 정보 | AA4: System | AB4: Veritas Volume 정보 | AG4: LDEV 정보 (AS-IS) | AJ4: LDEV 정보 (TO-BE)
A5: HOST | B5: Cluster | C5: VM Guest | D5: Folder | E5: (SCSI ID) | F5: Data Store | G5: Data Store NAA | H5: Data Store File | I5: RDM Device | J5: RDM NAA | L5: 활성 I/O | M5: Storage ID | N5: ID | O5: as-is ID | P5: SIZE | Q5: to-be LUN ID | R5: SIZE | S5: RDM Data Store | T5: Data Store File | U5: Storage ID | V5: Hostname | W5: Disk List | X5: TO-BE Disk List | Y5: OS Device | Z5: SIZE (GB) | AA5: Hostname | AB5: VG명 | AC5: LUN수 | AD5: Lun size(GB) | AE5: LUN name | AF5: LUN Addr | AG5: LUN ADDR | AH5: LUN Name | AI5: SIZE (GB) | AJ5: LUN ADDR | AK5: LUN Name | AL5: SIZE (GB) | AM5: 신규 rdmp 데이터스토어 name | AN5: 신규스토리지 rdm lun naa(두번째 시트에서 가지고옴-손대지말것) | AO5: rdm 파일생성 command(수정하지말것-중복제거 필요) | AP5: rdm 파일 삭제 command(중복제거 필요)
A6: 10.146.106.83 | B6: B-SV-PKB-RI | C6: pkbtsdbr1 | D6: 채권 | E6: 0,2 | F6: B-DR-RDMP-LUN196-PKBTSDBR | G6: naa.60060e80166221000001622100001f0e | H6: pkbtsdbr1/pkbtsdbr1.vmdk | I6: 020013000060060e8016622100000162210000004c4f50454e2d56 | J6: naa.60060e8016622100000162210000004c | K6: 10.146.106.83naa.60060e8016622100000162210000004c | L6: vmhba4:C0:T0:L19 | M6: 16221 | N6: 004c | O6: 00:4c | P6: 2.5003052 | Q6: =VLOOKUP($O6,'스토리지_LUN(TO-BE)'!$B$2:$G$347,4,FALSE) -> 00:4c | V6: =VLOOKUP($N6,OS_Disk!$A$2:$F$573,2,FALSE) -> pkbtsdbr1 | W6: =VLOOKUP($N6,OS_Disk!$A$2:$F$573,3,FALSE) -> hitachi_vsp0_004c | Y6: =VLOOKUP($N6,OS_Disk!$A$2:$F$573,4,FALSE) -> sdc | Z6: =VLOOKUP($N6,OS_Disk!$A$2:$F$573,6,FALSE) -> 25.000305 | AA6: =VLOOKUP($O6,Veritas_LUN!$D$3:$J$487,2,FALSE) -> pkbtsdbr1 | AB6: =VLOOKUP($O6,Veritas_LUN!$D$3:$J$487,3,FALSE) -> vg_ts1fs01 | AC6: =VLOOKUP($O6,Veritas_LUN!$D$3:$J$487,4,FALSE) -> 1 | AD6: =VLOOKUP($O6,Veritas_LUN!$D$3:$J$487,5,FALSE) -> 25 | AE6: =VLOOKUP($O6,Veritas_LUN!$D$3:$J$487,7,FALSE) -> vg_ts1fs01 | AF6: =VLOOKUP($O6,Veritas_LUN!$D$3:$K$487,8,FALSE) -> 00:4c | AG6: 00:4c | AH6: =VLOOKUP(AG6,'스토리지_LUN(AS-IS)'!$B$4:$G$541,4,FALSE) -> vg_ts1fs01 | AI6: =VLOOKUP(AG6,'스토리지_LUN(AS-IS)'!$B$4:$G$541,6,FALSE) -> 25 | AJ6: =VLOOKUP($AG6,'스토리지_LUN(TO-BE)'!$B$2:$G$347,4,FALSE) -> 00:4c | AM6: =VLOOKUP(F6,$F$580:$AM$608,34,FALSE) -> NB-DR-RDMP-0FAE-PKBTSDBR | AN6: =VLOOKUP(SUBSTITUTE(Q6,":",""),'naa정보-입력'!B4:C349,2,FALSE) -> naa.60060e8016622100000162210000004c | AO6: =_xlfn.CONCAT($AN$3,AN6," ","/vmfs/volumes/",AM6,"/",H6) -> vmkfstools -z /vmfs/devices/disks/naa.60060e8016622100000162210000004c /vmfs/volumes/NB-DR-RDMP-0FAE-PKBTSDBR/pkbtsdbr1/pkbtsdbr1.vmdk | AP6: rm -f /vmfs/volumes/NB-DR-RDMP-0FAE-PKBTSDBR/pkbtsdbr1/pkbtsdbr1.vmdk
A7: 10.146.106.83 | B7: B-SV-PKB-RI | C7: pkbtsdbr1 | D7: 채권 | E7: 0,3 | F7: B-DR-RDMP-LUN196-PKBTSDBR | G7: naa.60060e80166221000001622100001f0e | H7: pkbtsdbr1/pkbtsdbr1_1.vmdk | I7: 020063000060060e8016622100000162210000104c4f50454e2d56 | J7: naa.60060e8016622100000162210000104c | K7: 10.146.106.83naa.60060e8016622100000162210000104c | L7: vmhba4:C0:T0:L99 | M7: 16221 | N7: 104c | O7: 10:4c | P7: 50 | Q7: =VLOOKUP($O7,'스토리지_LUN(TO-BE)'!$B$2:$G$347,4,FALSE) -> 05:4c | V7: =VLOOKUP($N7,OS_Disk!$A$2:$F$573,2,FALSE) -> pkbtsdbr1 | W7: =VLOOKUP($N7,OS_Disk!$A$2:$F$573,3,FALSE) -> hitachi_vsp0_104c | Y7: =VLOOKUP($N7,OS_Disk!$A$2:$F$573,4,FALSE) -> sdd | Z7: =VLOOKUP($N7,OS_Disk!$A$2:$F$573,6,FALSE) -> 2.5003052 | AA7: =VLOOKUP($O7,Veritas_LUN!$D$3:$J$487,2,FALSE) -> pkbtsdbr1 | AB7: =VLOOKUP($O7,Veritas_LUN!$D$3:$J$487,3,FALSE) -> vvr_vg_ts1fs01 | AC7: =VLOOKUP($O7,Veritas_LUN!$D$3:$J$487,4,FALSE) -> 1 | AD7: =VLOOKUP($O7,Veritas_LUN!$D$3:$J$487,5,FALSE) -> 2.5 | AE7: =VLOOKUP($O7,Veritas_LUN!$D$3:$J$487,7,FALSE) -> VVR-vg_ts1fs01 | AF7: =VLOOKUP($O7,Veritas_LUN!$D$3:$K$487,8,FALSE) -> 10:4c | AG7: 10:4c | AH7: =VLOOKUP(AG7,'스토리지_LUN(AS-IS)'!$B$4:$G$541,4,FALSE) -> VVR-vg_ts1fs01 | AI7: =VLOOKUP(AG7,'스토리지_LUN(AS-IS)'!$B$4:$G$541,6,FALSE) -> 2.5 | AJ7: =VLOOKUP($AG7,'스토리지_LUN(TO-BE)'!$B$2:$G$347,4,FALSE) -> 05:4c | AM7: =VLOOKUP(F7,$F$580:$AM$608,34,FALSE) -> NB-DR-RDMP-0FAE-PKBTSDBR | AN7: =VLOOKUP(SUBSTITUTE(Q7,":",""),'naa정보-입력'!B5:C350,2,FALSE) -> #N/A | AO7: =_xlfn.CONCAT($AN$3,AN7," ","/vmfs/volumes/",AM7,"/",H7) -> #N/A | AP7: rm -f /vmfs/volumes/NB-DR-RDMP-0FAE-PKBTSDBR/pkbtsdbr1/pkbtsdbr1_1.vmdk
A8: 10.146.106.83 | B8: B-SV-PKB-RI | C8: pkbtsdbr1 | D8: 채권 | E8: 1,0 | F8: B-DR-RDMP-LUN196-PKBTSDBR | G8: naa.60060e80166221000001622100001f0e | H8: pkbtsdbr1/pkbtsdbr1_2.vmdk | I8: 020015000060060e8016622100000162210000004e4f50454e2d56 | J8: naa.60060e8016622100000162210000004e | K8: 10.146.106.83naa.60060e8016622100000162210000004e | L8: vmhba2:C0:T1:L21 | M8: 16221 | N8: 004e | O8: 00:4e | P8: 20.00061 | Q8: =VLOOKUP($O8,'스토리지_LUN(TO-BE)'!$B$2:$G$347,4,FALSE) -> 00:4e | V8: =VLOOKUP($N8,OS_Disk!$A$2:$F$573,2,FALSE) -> pkbtsdbr1 | W8: =VLOOKUP($N8,OS_Disk!$A$2:$F$573,3,FALSE) -> hitachi_vsp0_004e | Y8: =VLOOKUP($N8,OS_Disk!$A$2:$F$573,4,FALSE) -> sdi | Z8: =VLOOKUP($N8,OS_Disk!$A$2:$F$573,6,FALSE) -> 210 | AA8: =VLOOKUP($O8,Veritas_LUN!$D$3:$J$487,2,FALSE) -> pkbtsdbr1/pkbtsdbr2 | AB8: =VLOOKUP($O8,Veritas_LUN!$D$3:$J$487,3,FALSE) -> vg_tscfs01 | AC8: =VLOOKUP($O8,Veritas_LUN!$D$3:$J$487,4,FALSE) -> 1 | AD8: =VLOOKUP($O8,Veritas_LUN!$D$3:$J$487,5,FALSE) -> 210 | AE8: =VLOOKUP($O8,Veritas_LUN!$D$3:$J$487,7,FALSE) -> vg_tscfs01 | AF8: =VLOOKUP($O8,Veritas_LUN!$D$3:$K$487,8,FALSE) -> 00:4e | AG8: 00:4e | AH8: =VLOOKUP(AG8,'스토리지_LUN(AS-IS)'!$B$4:$G$541,4,FALSE) -> vg_tscfs01 | AI8: =VLOOKUP(AG8,'스토리지_LUN(AS-IS)'!$B$4:$G$541,6,FALSE) -> 210 | AJ8: =VLOOKUP($AG8,'스토리지_LUN(TO-BE)'!$B$2:$G$347,4,FALSE) -> 00:4e | AM8: =VLOOKUP(F8,$F$580:$AM$608,34,FALSE) -> NB-DR-RDMP-0FAE-PKBTSDBR | AN8: =VLOOKUP(SUBSTITUTE(Q8,":",""),'naa정보-입력'!B6:C351,2,FALSE) -> #N/A | AO8: =_xlfn.CONCAT($AN$3,AN8," ","/vmfs/volumes/",AM8,"/",H8) -> #N/A | AP8: rm -f /vmfs/volumes/NB-DR-RDMP-0FAE-PKBTSDBR/pkbtsdbr1/pkbtsdbr1_2.vmdk
A9: 10.146.106.83 | B9: B-SV-PKB-RI | C9: pkbtsdbr1 | D9: 채권 | E9: 1,1 | F9: B-DR-RDMP-LUN196-PKBTSDBR | G9: naa.60060e80166221000001622100001f0e | H9: pkbtsdbr1/pkbtsdbr1_14.vmdk | I9: 02001a000060060e801662210000016221000001044f50454e2d56 | J9: naa.60060e80166221000001622100000104 | K9: 10.146.106.83naa.60060e80166221000001622100000104 | L9: vmhba2:C0:T1:L26 | M9: 16221 | N9: 0104 | O9: 01:04 | P9: 35.00061 | Q9: =VLOOKUP($O9,'스토리지_LUN(TO-BE)'!$B$2:$G$347,4,FALSE) -> 01:04 | V9: =VLOOKUP($N9,OS_Disk!$A$2:$F$573,2,FALSE) -> pkbtsdbr1 | W9: =VLOOKUP($N9,OS_Disk!$A$2:$F$573,3,FALSE) -> hitachi_vsp0_0104 | Y9: =VLOOKUP($N9,OS_Disk!$A$2:$F$573,4,FALSE) -> sdj | Z9: =VLOOKUP($N9,OS_Disk!$A$2:$F$573,6,FALSE) -> 20.00061 | AA9: =VLOOKUP($O9,Veritas_LUN!$D$3:$J$487,2,FALSE) -> pkbtsdbr1/pkbtsdbr2 | AB9: =VLOOKUP($O9,Veritas_LUN!$D$3:$J$487,3,FALSE) -> vg_tssys01_01 | AC9: =VLOOKUP($O9,Veritas_LUN!$D$3:$J$487,4,FALSE) -> 1 | AD9: =VLOOKUP($O9,Veritas_LUN!$D$3:$J$487,5,FALSE) -> 20 | AE9: =VLOOKUP($O9,Veritas_LUN!$D$3:$J$487,7,FALSE) -> vg_tssys_new | AF9: =VLOOKUP($O9,Veritas_LUN!$D$3:$K$487,8,FALSE) -> 01:04 | AG9: 01:04 | AH9: =VLOOKUP(AG9,'스토리지_LUN(AS-IS)'!$B$4:$G$541,4,FALSE) -> vg_tssys_new | AI9: =VLOOKUP(AG9,'스토리지_LUN(AS-IS)'!$B$4:$G$541,6,FALSE) -> 20 | AJ9: =VLOOKUP($AG9,'스토리지_LUN(TO-BE)'!$B$2:$G$347,4,FALSE) -> 01:04 | AM9: =VLOOKUP(F9,$F$580:$AM$608,34,FALSE) -> NB-DR-RDMP-0FAE-PKBTSDBR | AN9: =VLOOKUP(SUBSTITUTE(Q9,":",""),'naa정보-입력'!B7:C352,2,FALSE) -> #N/A | AO9: =_xlfn.CONCAT($AN$3,AN9," ","/vmfs/volumes/",AM9,"/",H9) -> #N/A | AP9: rm -f /vmfs/volumes/NB-DR-RDMP-0FAE-PKBTSDBR/pkbtsdbr1/pkbtsdbr1_14.vmdk
A10: 10.146.106.83 | B10: B-SV-PKB-RI | C10: pkbtsdbr1 | D10: 채권 | E10: 1,2 | F10: B-DR-RDMP-LUN196-PKBTSDBR | G10: naa.60060e80166221000001622100001f0e | H10: pkbtsdbr1/pkbtsdbr1_4.vmdk | I10: 020017000060060e801662210000016221000000504f50454e2d56 | J10: naa.60060e80166221000001622100000050 | K10: 10.146.106.83naa.60060e80166221000001622100000050 | L10: vmhba2:C0:T1:L23 | M10: 16221 | N10: 0050 | O10: 00:50 | P10: 110.00061 | Q10: =VLOOKUP($O10,'스토리지_LUN(TO-BE)'!$B$2:$G$347,4,FALSE) -> 00:50 | V10: =VLOOKUP($N10,OS_Disk!$A$2:$F$573,2,FALSE) -> pkbtsdbr1 | W10: =VLOOKUP($N10,OS_Disk!$A$2:$F$573,3,FALSE) -> hitachi_vsp0_0050 | Y10: =VLOOKUP($N10,OS_Disk!$A$2:$F$573,4,FALSE) -> sdk | Z10: =VLOOKUP($N10,OS_Disk!$A$2:$F$573,6,FALSE) -> 35.00061 | AA10: =VLOOKUP($O10,Veritas_LUN!$D$3:$J$487,2,FALSE) -> pkbtsdbr1/pkbtsdbr2 | AB10: =VLOOKUP($O10,Veritas_LUN!$D$3:$J$487,3,FALSE) -> vg_tssys02 | AC10: =VLOOKUP($O10,Veritas_LUN!$D$3:$J$487,4,FALSE) -> 1 | AD10: =VLOOKUP($O10,Veritas_LUN!$D$3:$J$487,5,FALSE) -> 35 | AE10: =VLOOKUP($O10,Veritas_LUN!$D$3:$J$487,7,FALSE) -> vg_tssys02 | AF10: =VLOOKUP($O10,Veritas_LUN!$D$3:$K$487,8,FALSE) -> 00:50 | AG10: 00:50 | AH10: =VLOOKUP(AG10,'스토리지_LUN(AS-IS)'!$B$4:$G$541,4,FALSE) -> vg_tssys02 | AI10: =VLOOKUP(AG10,'스토리지_LUN(AS-IS)'!$B$4:$G$541,6,FALSE) -> 35 | AJ10: =VLOOKUP($AG10,'스토리지_LUN(TO-BE)'!$B$2:$G$347,4,FALSE) -> 00:50 | AM10: =VLOOKUP(F10,$F$580:$AM$608,34,FALSE) -> NB-DR-RDMP-0FAE-PKBTSDBR | AN10: =VLOOKUP(SUBSTITUTE(Q10,":",""),'naa정보-입력'!B8:C353,2,FALSE) -> #N/A | AO10: =_xlfn.CONCAT($AN$3,AN10," ","/vmfs/volumes/",AM10,"/",H10) -> #N/A | AP10: rm -f /vmfs/volumes/NB-DR-RDMP-0FAE-PKBTSDBR/pkbtsdbr1/pkbtsdbr1_4.vmdk
A11: 10.146.106.83 | B11: B-SV-PKB-RI | C11: pkbtsdbr1 | D11: 채권 | E11: 1,3 | F11: B-DR-RDMP-LUN196-PKBTSDBR | G11: naa.60060e80166221000001622100001f0e | H11: pkbtsdbr1/pkbtsdbr1_5.vmdk | I11: 020018000060060e801662210000016221000000514f50454e2d56 | J11: naa.60060e80166221000001622100000051 | K11: 10.146.106.83naa.60060e80166221000001622100000051 | L11: vmhba2:C0:T1:L24 | M11: 16221 | N11: 0051 | O11: 00:51 | P11: 65.00061 | Q11: =VLOOKUP($O11,'스토리지_LUN(TO-BE)'!$B$2:$G$347,4,FALSE) -> 00:51 | V11: =VLOOKUP($N11,OS_Disk!$A$2:$F$573,2,FALSE) -> pkbtsdbr1 | W11: =VLOOKUP($N11,OS_Disk!$A$2:$F$573,3,FALSE) -> hitachi_vsp0_0051 | Y11: =VLOOKUP($N11,OS_Disk!$A$2:$F$573,4,FALSE) -> sdl | Z11: =VLOOKUP($N11,OS_Disk!$A$2:$F$573,6,FALSE) -> 525 | AA11: =VLOOKUP($O11,Veritas_LUN!$D$3:$J$487,2,FALSE) -> pkbtsdbr1/pkbtsdbr2 | AB11: =VLOOKUP($O11,Veritas_LUN!$D$3:$J$487,3,FALSE) -> vg_tsdb01 | AC11: =VLOOKUP($O11,Veritas_LUN!$D$3:$J$487,4,FALSE) -> 1 | AD11: =VLOOKUP($O11,Veritas_LUN!$D$3:$J$487,5,FALSE) -> 525 | AE11: =VLOOKUP($O11,Veritas_LUN!$D$3:$J$487,7,FALSE) -> vg_tsdb01 | AF11: =VLOOKUP($O11,Veritas_LUN!$D$3:$K$487,8,FALSE) -> 00:51 | AG11: 00:51 | AH11: =VLOOKUP(AG11,'스토리지_LUN(AS-IS)'!$B$4:$G$541,4,FALSE) -> vg_tsdb01 | AI11: =VLOOKUP(AG11,'스토리지_LUN(AS-IS)'!$B$4:$G$541,6,FALSE) -> 525 | AJ11: =VLOOKUP($AG11,'스토리지_LUN(TO-BE)'!$B$2:$G$347,4,FALSE) -> 00:51 | AM11: =VLOOKUP(F11,$F$580:$AM$608,34,FALSE) -> NB-DR-RDMP-0FAE-PKBTSDBR | AN11: =VLOOKUP(SUBSTITUTE(Q11,":",""),'naa정보-입력'!B9:C354,2,FALSE) -> #N/A | AO11: =_xlfn.CONCAT($AN$3,AN11," ","/vmfs/volumes/",AM11,"/",H11) -> #N/A | AP11: rm -f /vmfs/volumes/NB-DR-RDMP-0FAE-PKBTSDBR/pkbtsdbr1/pkbtsdbr1_5.vmdk
A12: 10.146.106.83 | B12: B-SV-PKB-RI | C12: pkbtsdbr1 | D12: 채권 | E12: 1,4 | F12: B-DR-RDMP-LUN196-PKBTSDBR | G12: naa.60060e80166221000001622100001f0e | H12: pkbtsdbr1/pkbtsdbr1_6.vmdk | I12: 020019000060060e801662210000016221000000524f50454e2d56 | J12: naa.60060e80166221000001622100000052 | K12: 10.146.106.83naa.60060e80166221000001622100000052 | L12: vmhba2:C0:T1:L25 | M12: 16221 | N12: 0052 | O12: 00:52 | P12: 20.00061 | Q12: =VLOOKUP($O12,'스토리지_LUN(TO-BE)'!$B$2:$G$347,4,FALSE) -> 00:52 | V12: =VLOOKUP($N12,OS_Disk!$A$2:$F$573,2,FALSE) -> pkbtsdbr1 | W12: =VLOOKUP($N12,OS_Disk!$A$2:$F$573,3,FALSE) -> hitachi_vsp0_0052 | Y12: =VLOOKUP($N12,OS_Disk!$A$2:$F$573,4,FALSE) -> sdm | Z12: =VLOOKUP($N12,OS_Disk!$A$2:$F$573,6,FALSE) -> 295.00031 | AA12: =VLOOKUP($O12,Veritas_LUN!$D$3:$J$487,2,FALSE) -> pkbtsdbr1/pkbtsdbr2 | AB12: =VLOOKUP($O12,Veritas_LUN!$D$3:$J$487,3,FALSE) -> vg_tsidx01 | AC12: =VLOOKUP($O12,Veritas_LUN!$D$3:$J$487,4,FALSE) -> 1 | AD12: =VLOOKUP($O12,Veritas_LUN!$D$3:$J$487,5,FALSE) -> 295 | AE12: =VLOOKUP($O12,Veritas_LUN!$D$3:$J$487,7,FALSE) -> vg_tsidx01 | AF12: =VLOOKUP($O12,Veritas_LUN!$D$3:$K$487,8,FALSE) -> 00:52 | AG12: 00:52 | AH12: =VLOOKUP(AG12,'스토리지_LUN(AS-IS)'!$B$4:$G$541,4,FALSE) -> vg_tsidx01 | AI12: =VLOOKUP(AG12,'스토리지_LUN(AS-IS)'!$B$4:$G$541,6,FALSE) -> 295 | AJ12: =VLOOKUP($AG12,'스토리지_LUN(TO-BE)'!$B$2:$G$347,4,FALSE) -> 00:52 | AM12: =VLOOKUP(F12,$F$580:$AM$608,34,FALSE) -> NB-DR-RDMP-0FAE-PKBTSDBR | AN12: =VLOOKUP(SUBSTITUTE(Q12,":",""),'naa정보-입력'!B10:C355,2,FALSE) -> #N/A | AO12: =_xlfn.CONCAT($AN$3,AN12," ","/vmfs/volumes/",AM12,"/",H12) -> #N/A | AP12: rm -f /vmfs/volumes/NB-DR-RDMP-0FAE-PKBTSDBR/pkbtsdbr1/pkbtsdbr1_6.vmdk
A13: 10.146.106.83 | B13: B-SV-PKB-RI | C13: pkbtsdbr1 | D13: 채권 | E13: 1,5 | F13: B-DR-RDMP-LUN196-PKBTSDBR | G13: naa.60060e80166221000001622100001f0e | H13: pkbtsdbr1/pkbtsdbr1_15.vmdk | I13: 02001b000060060e801662210000016221000001054f50454e2d56 | J13: naa.60060e80166221000001622100000105 | K13: 10.146.106.83naa.60060e80166221000001622100000105 | L13: vmhba2:C0:T1:L27 | M13: 16221 | N13: 0105 | O13: 01:05 | P13: 21.000366 | Q13: =VLOOKUP($O13,'스토리지_LUN(TO-BE)'!$B$2:$G$347,4,FALSE) -> 01:05 | V13: =VLOOKUP($N13,OS_Disk!$A$2:$F$573,2,FALSE) -> pkbtsdbr1 | W13: =VLOOKUP($N13,OS_Disk!$A$2:$F$573,3,FALSE) -> hitachi_vsp0_0105 | Y13: =VLOOKUP($N13,OS_Disk!$A$2:$F$573,4,FALSE) -> sdn | Z13: =VLOOKUP($N13,OS_Disk!$A$2:$F$573,6,FALSE) -> 20.00061 | AA13: =VLOOKUP($O13,Veritas_LUN!$D$3:$J$487,2,FALSE) -> pkbtsdbr1/pkbtsdbr2 | AB13: =VLOOKUP($O13,Veritas_LUN!$D$3:$J$487,3,FALSE) -> vg_tssys01_02 | AC13: =VLOOKUP($O13,Veritas_LUN!$D$3:$J$487,4,FALSE) -> 1 | AD13: =VLOOKUP($O13,Veritas_LUN!$D$3:$J$487,5,FALSE) -> 20 | AE13: =VLOOKUP($O13,Veritas_LUN!$D$3:$J$487,7,FALSE) -> vg_tssys_new | AF13: =VLOOKUP($O13,Veritas_LUN!$D$3:$K$487,8,FALSE) -> 01:05 | AG13: 01:05 | AH13: =VLOOKUP(AG13,'스토리지_LUN(AS-IS)'!$B$4:$G$541,4,FALSE) -> vg_tssys_new | AI13: =VLOOKUP(AG13,'스토리지_LUN(AS-IS)'!$B$4:$G$541,6,FALSE) -> 20 | AJ13: =VLOOKUP($AG13,'스토리지_LUN(TO-BE)'!$B$2:$G$347,4,FALSE) -> 01:05 | AM13: =VLOOKUP(F13,$F$580:$AM$608,34,FALSE) -> NB-DR-RDMP-0FAE-PKBTSDBR | AN13: =VLOOKUP(SUBSTITUTE(Q13,":",""),'naa정보-입력'!B11:C356,2,FALSE) -> #N/A | AO13: =_xlfn.CONCAT($AN$3,AN13," ","/vmfs/volumes/",AM13,"/",H13) -> #N/A | AP13: rm -f /vmfs/volumes/NB-DR-RDMP-0FAE-PKBTSDBR/pkbtsdbr1/pkbtsdbr1_15.vmdk
A14: 10.146.106.83 | B14: B-SV-PKB-RI | C14: pkbtsdbr1 | D14: 채권 | E14: 2,0 | F14: B-DR-RDMP-LUN196-PKBTSDBR | G14: naa.60060e80166221000001622100001f0e | H14: pkbtsdbr1/pkbtsdbr1_7.vmdk | I14: 020065000060060e8016622100000162210000104e4f50454e2d56 | J14: naa.60060e8016622100000162210000104e | K14: 10.146.106.83naa.60060e8016622100000162210000104e | L14: vmhba2:C0:T1:L101 | M14: 16221 | N14: 104e | O14: 10:4e | P14: 3.0001831 | Q14: =VLOOKUP($O14,'스토리지_LUN(TO-BE)'!$B$2:$G$347,4,FALSE) -> 05:4e | V14: =VLOOKUP($N14,OS_Disk!$A$2:$F$573,2,FALSE) -> pkbtsdbr1 | W14: =VLOOKUP($N14,OS_Disk!$A$2:$F$573,3,FALSE) -> hitachi_vsp0_104e | Y14: =VLOOKUP($N14,OS_Disk!$A$2:$F$573,4,FALSE) -> sdo | Z14: =VLOOKUP($N14,OS_Disk!$A$2:$F$573,6,FALSE) -> 21.000366 | AA14: =VLOOKUP($O14,Veritas_LUN!$D$3:$J$487,2,FALSE) -> pkbtsdbr1/pkbtsdbr2 | AB14: =VLOOKUP($O14,Veritas_LUN!$D$3:$J$487,3,FALSE) -> none | AC14: =VLOOKUP($O14,Veritas_LUN!$D$3:$J$487,4,FALSE) -> 1 | AD14: =VLOOKUP($O14,Veritas_LUN!$D$3:$J$487,5,FALSE) -> 21 | AE14: =VLOOKUP($O14,Veritas_LUN!$D$3:$J$487,7,FALSE) -> VVR-vg_tscfs01 | AF14: =VLOOKUP($O14,Veritas_LUN!$D$3:$K$487,8,FALSE) -> 10:4e | AG14: 10:4e | AH14: =VLOOKUP(AG14,'스토리지_LUN(AS-IS)'!$B$4:$G$541,4,FALSE) -> VVR-vg_tscfs01 | AI14: =VLOOKUP(AG14,'스토리지_LUN(AS-IS)'!$B$4:$G$541,6,FALSE) -> 21 | AJ14: =VLOOKUP($AG14,'스토리지_LUN(TO-BE)'!$B$2:$G$347,4,FALSE) -> 05:4e | AM14: =VLOOKUP(F14,$F$580:$AM$608,34,FALSE) -> NB-DR-RDMP-0FAE-PKBTSDBR | AN14: =VLOOKUP(SUBSTITUTE(Q14,":",""),'naa정보-입력'!B12:C357,2,FALSE) -> #N/A | AO14: =_xlfn.CONCAT($AN$3,AN14," ","/vmfs/volumes/",AM14,"/",H14) -> #N/A | AP14: rm -f /vmfs/volumes/NB-DR-RDMP-0FAE-PKBTSDBR/pkbtsdbr1/pkbtsdbr1_7.vmdk
A15: 10.146.106.83 | B15: B-SV-PKB-RI | C15: pkbtsdbr1 | D15: 채권 | E15: 2,1 | F15: B-DR-RDMP-LUN196-PKBTSDBR | G15: naa.60060e80166221000001622100001f0e | H15: pkbtsdbr1/pkbtsdbr1_16.vmdk | I15: 020069000060060e801662210000016221000011044f50454e2d56 | J15: naa.60060e80166221000001622100001104 | K15: 10.146.106.83naa.60060e80166221000001622100001104 | L15: vmhba2:C0:T1:L105 | M15: 16221 | N15: 1104 | O15: 11:04 | P15: 11.000061 | Q15: =VLOOKUP($O15,'스토리지_LUN(TO-BE)'!$B$2:$G$347,4,FALSE) -> 05:85 | V15: =VLOOKUP($N15,OS_Disk!$A$2:$F$573,2,FALSE) -> pkbtsdbr1 | W15: =VLOOKUP($N15,OS_Disk!$A$2:$F$573,3,FALSE) -> hitachi_vsp0_1104 | Y15: =VLOOKUP($N15,OS_Disk!$A$2:$F$573,4,FALSE) -> sdp | Z15: =VLOOKUP($N15,OS_Disk!$A$2:$F$573,6,FALSE) -> 3.0001831 | AA15: =VLOOKUP($O15,Veritas_LUN!$D$3:$J$487,2,FALSE) -> pkbtsdbr1/pkbtsdbr2 | AB15: =VLOOKUP($O15,Veritas_LUN!$D$3:$J$487,3,FALSE) -> vvr_vg_tssys01_01 | AC15: =VLOOKUP($O15,Veritas_LUN!$D$3:$J$487,4,FALSE) -> 1 | AD15: =VLOOKUP($O15,Veritas_LUN!$D$3:$J$487,5,FALSE) -> 3 | AE15: =VLOOKUP($O15,Veritas_LUN!$D$3:$J$487,7,FALSE) -> VVR_vg_tssys_new | AF15: =VLOOKUP($O15,Veritas_LUN!$D$3:$K$487,8,FALSE) -> 11:04 | AG15: 11:04 | AH15: =VLOOKUP(AG15,'스토리지_LUN(AS-IS)'!$B$4:$G$541,4,FALSE) -> VVR_vg_tssys_new | AI15: =VLOOKUP(AG15,'스토리지_LUN(AS-IS)'!$B$4:$G$541,6,FALSE) -> 3 | AJ15: =VLOOKUP($AG15,'스토리지_LUN(TO-BE)'!$B$2:$G$347,4,FALSE) -> 05:85 | AM15: =VLOOKUP(F15,$F$580:$AM$608,34,FALSE) -> NB-DR-RDMP-0FAE-PKBTSDBR | AN15: =VLOOKUP(SUBSTITUTE(Q15,":",""),'naa정보-입력'!B13:C358,2,FALSE) -> #N/A | AO15: =_xlfn.CONCAT($AN$3,AN15," ","/vmfs/volumes/",AM15,"/",H15) -> #N/A | AP15: rm -f /vmfs/volumes/NB-DR-RDMP-0FAE-PKBTSDBR/pkbtsdbr1/pkbtsdbr1_16.vmdk
A16: 10.146.106.83 | B16: B-SV-PKB-RI | C16: pkbtsdbr1 | D16: 채권 | E16: 2,2 | F16: B-DR-RDMP-LUN196-PKBTSDBR | G16: naa.60060e80166221000001622100001f0e | H16: pkbtsdbr1/pkbtsdbr1_9.vmdk | I16: 020067000060060e801662210000016221000010514f50454e2d56 | J16: naa.60060e80166221000001622100001051 | K16: 10.146.106.83naa.60060e80166221000001622100001051 | L16: vmhba2:C0:T1:L103 | M16: 16221 | N16: 1051 | O16: 10:51 | P16: 6.5002441 | Q16: =VLOOKUP($O16,'스토리지_LUN(TO-BE)'!$B$2:$G$347,4,FALSE) -> 05:51 | V16: =VLOOKUP($N16,OS_Disk!$A$2:$F$573,2,FALSE) -> pkbtsdbr1 | W16: =VLOOKUP($N16,OS_Disk!$A$2:$F$573,3,FALSE) -> hitachi_vsp0_1051 | Y16: =VLOOKUP($N16,OS_Disk!$A$2:$F$573,4,FALSE) -> sdq | Z16: =VLOOKUP($N16,OS_Disk!$A$2:$F$573,6,FALSE) -> 57.000732 | AA16: =VLOOKUP($O16,Veritas_LUN!$D$3:$J$487,2,FALSE) -> pkbtsdbr1/pkbtsdbr2 | AB16: =VLOOKUP($O16,Veritas_LUN!$D$3:$J$487,3,FALSE) -> vvr_vg_tsdb01 | AC16: =VLOOKUP($O16,Veritas_LUN!$D$3:$J$487,4,FALSE) -> 1 | AD16: =VLOOKUP($O16,Veritas_LUN!$D$3:$J$487,5,FALSE) -> 57 | AE16: =VLOOKUP($O16,Veritas_LUN!$D$3:$J$487,7,FALSE) -> VVR-vg_tsdb01 | AF16: =VLOOKUP($O16,Veritas_LUN!$D$3:$K$487,8,FALSE) -> 10:51 | AG16: 10:51 | AH16: =VLOOKUP(AG16,'스토리지_LUN(AS-IS)'!$B$4:$G$541,4,FALSE) -> VVR-vg_tsdb01 | AI16: =VLOOKUP(AG16,'스토리지_LUN(AS-IS)'!$B$4:$G$541,6,FALSE) -> 57 | AJ16: =VLOOKUP($AG16,'스토리지_LUN(TO-BE)'!$B$2:$G$347,4,FALSE) -> 05:51 | AM16: =VLOOKUP(F16,$F$580:$AM$608,34,FALSE) -> NB-DR-RDMP-0FAE-PKBTSDBR | AN16: =VLOOKUP(SUBSTITUTE(Q16,":",""),'naa정보-입력'!B14:C359,2,FALSE) -> #N/A | AO16: =_xlfn.CONCAT($AN$3,AN16," ","/vmfs/volumes/",AM16,"/",H16) -> #N/A | AP16: rm -f /vmfs/volumes/NB-DR-RDMP-0FAE-PKBTSDBR/pkbtsdbr1/pkbtsdbr1_9.vmdk
A17: 10.146.106.83 | B17: B-SV-PKB-RI | C17: pkbtsdbr1 | D17: 채권 | E17: 2,3 | F17: B-DR-RDMP-LUN196-PKBTSDBR | G17: naa.60060e80166221000001622100001f0e | H17: pkbtsdbr1/pkbtsdbr1_10.vmdk | I17: 020068000060060e801662210000016221000010524f50454e2d56 | J17: naa.60060e80166221000001622100001052 | K17: 10.146.106.83naa.60060e80166221000001622100001052 | L17: vmhba2:C0:T1:L104 | M17: 16221 | N17: 1052 | O17: 10:52 | P17: 3.0001831 | Q17: =VLOOKUP($O17,'스토리지_LUN(TO-BE)'!$B$2:$G$347,4,FALSE) -> 05:52 | V17: =VLOOKUP($N17,OS_Disk!$A$2:$F$573,2,FALSE) -> pkbtsdbr1 | W17: =VLOOKUP($N17,OS_Disk!$A$2:$F$573,3,FALSE) -> hitachi_vsp0_1052 | Y17: =VLOOKUP($N17,OS_Disk!$A$2:$F$573,4,FALSE) -> sdr | Z17: =VLOOKUP($N17,OS_Disk!$A$2:$F$573,6,FALSE) -> 33.000183 | AA17: =VLOOKUP($O17,Veritas_LUN!$D$3:$J$487,2,FALSE) -> pkbtsdbr1/pkbtsdbr2 | AB17: =VLOOKUP($O17,Veritas_LUN!$D$3:$J$487,3,FALSE) -> vvr_vg_tsidx01 | AC17: =VLOOKUP($O17,Veritas_LUN!$D$3:$J$487,4,FALSE) -> 1 | AD17: =VLOOKUP($O17,Veritas_LUN!$D$3:$J$487,5,FALSE) -> 33 | AE17: =VLOOKUP($O17,Veritas_LUN!$D$3:$J$487,7,FALSE) -> VVR-vg_tsidx01 | AF17: =VLOOKUP($O17,Veritas_LUN!$D$3:$K$487,8,FALSE) -> 10:52 | AG17: 10:52 | AH17: =VLOOKUP(AG17,'스토리지_LUN(AS-IS)'!$B$4:$G$541,4,FALSE) -> VVR-vg_tsidx01 | AI17: =VLOOKUP(AG17,'스토리지_LUN(AS-IS)'!$B$4:$G$541,6,FALSE) -> 33 | AJ17: =VLOOKUP($AG17,'스토리지_LUN(TO-BE)'!$B$2:$G$347,4,FALSE) -> 05:52 | AM17: =VLOOKUP(F17,$F$580:$AM$608,34,FALSE) -> NB-DR-RDMP-0FAE-PKBTSDBR | AN17: =VLOOKUP(SUBSTITUTE(Q17,":",""),'naa정보-입력'!B15:C360,2,FALSE) -> #N/A | AO17: =_xlfn.CONCAT($AN$3,AN17," ","/vmfs/volumes/",AM17,"/",H17) -> #N/A | AP17: rm -f /vmfs/volumes/NB-DR-RDMP-0FAE-PKBTSDBR/pkbtsdbr1/pkbtsdbr1_10.vmdk
... A293: 10.146.106.58 | B293: B-SV-PKC-RE | C293: pkcrddbr1 | D293: 공통 | E293: 3,2 | F293: B-DR-RDMP-LUN197-PKCRDDBR | G293: naa.60060e80166221000001622100001f14 | H293: pkcrddbr1/pkcrddbr1_13.vmdk | I293: 0200b1000060060e80166221000001622100000f3e4f50454e2d56 | J293: naa.60060e80166221000001622100000f3e | K293: 10.146.106.58naa.60060e80166221000001622100000f3e | L293: vmhba4:C0:T2:L177 | M293: 16221 | N293: 0f32 | O293: 0f:3e | P293: 40 | Q293: =VLOOKUP($O293,'스토리지_LUN(TO-BE)'!$B$2:$G$347,4,FALSE) -> 0f:3e | V293: =VLOOKUP($N293,OS_Disk!$A$2:$F$573,2,FALSE) -> pkceuapr1 | W293: =VLOOKUP($N293,OS_Disk!$A$2:$F$573,3,FALSE) -> hitachi_vsp0_0f32 | Y293: =VLOOKUP($N293,OS_Disk!$A$2:$F$573,4,FALSE) -> sdg | Z293: =VLOOKUP($N293,OS_Disk!$A$2:$F$573,6,FALSE) -> 0.20050049 | AA293: =VLOOKUP($O293,Veritas_LUN!$D$3:$J$487,2,FALSE) -> pkcrddbr1/pkcrddbr2 | AB293: =VLOOKUP($O293,Veritas_LUN!$D$3:$J$487,3,FALSE) -> Lock Device | AC293: =VLOOKUP($O293,Veritas_LUN!$D$3:$J$487,4,FALSE) -> 1 | AD293: =VLOOKUP($O293,Veritas_LUN!$D$3:$J$487,5,FALSE) -> 0.2 | AE293: =VLOOKUP($O293,Veritas_LUN!$D$3:$J$487,7,FALSE) -> Lock Device | AF293: =VLOOKUP($O293,Veritas_LUN!$D$3:$K$487,8,FALSE) -> 0f:3e | AG293: 0f:3e | AH293: =VLOOKUP(AG293,'스토리지_LUN(AS-IS)'!$B$4:$G$541,4,FALSE) -> Lock Device | AI293: =VLOOKUP(AG293,'스토리지_LUN(AS-IS)'!$B$4:$G$541,6,FALSE) -> 0.2 | AJ293: =VLOOKUP($AG293,'스토리지_LUN(TO-BE)'!$B$2:$G$347,4,FALSE) -> 0f:3e | AM293: =VLOOKUP(F293,$F$580:$AM$608,34,FALSE) -> NB-DR-RDMP-0FB4-PKCRDDBR | AN293: =VLOOKUP(SUBSTITUTE(Q293,":",""),'naa정보-입력'!B291:C636,2,FALSE) -> #N/A | AO293: =_xlfn.CONCAT($AN$3,AN293," ","/vmfs/volumes/",AM293,"/",H293) -> #N/A | AP293: rm -f /vmfs/volumes/NB-DR-RDMP-0FB4-PKCRDDBR/pkcrddbr1/pkcrddbr1_13.vmdk
A294: 10.146.106.46 | B294: B-SV-PKM-RE | C294: pkmmssmr1 | D294: 관리 | E294: 0,2 | F294: B-DR-RDMP-LUN195-PKCMSSMR | G294: naa.60060e80166221000001622100001f1c | H294: pkcmssmr2/pkcmssmr2.vmdk | I294: 020004000060060e801662210000016221000000764f50454e2d56 | J294: naa.60060e80166221000001622100000076 | K294: 10.146.106.46naa.60060e80166221000001622100000076 | L294: vmhba4:C0:T0:L4 | M294: 16221 | N294: 0076 | O294: 00:76 | P294: 50 | Q294: =VLOOKUP($O294,'스토리지_LUN(TO-BE)'!$B$2:$G$347,4,FALSE) -> 00:76 | V294: pkmmssmr1 | W294: =VLOOKUP($N294,OS_Disk!$A$2:$F$574,3,FALSE) -> pkmmssmr1_lun | Y294: =VLOOKUP($N294,OS_Disk!$A$2:$F$574,4,FALSE) -> D 드라이브 | Z294: =VLOOKUP($N294,OS_Disk!$A$2:$F$574,6,FALSE) -> 220 | AA294: =VLOOKUP($O294,Veritas_LUN!$D$3:$J$487,2,FALSE) -> pkmmssmr1 | AB294: =VLOOKUP($O294,Veritas_LUN!$D$3:$J$487,3,FALSE) -> DR-SMS | AC294: =VLOOKUP($O294,Veritas_LUN!$D$3:$J$487,4,FALSE) -> 1 | AD294: =VLOOKUP($O294,Veritas_LUN!$D$3:$J$487,5,FALSE) -> 220 | AE294: =VLOOKUP($O294,Veritas_LUN!$D$3:$J$487,7,FALSE) -> vg_msfs02 | AF294: =VLOOKUP($O294,Veritas_LUN!$D$3:$K$487,8,FALSE) -> 00:76 | AG294: 00:76 | AH294: =VLOOKUP(AG294,'스토리지_LUN(AS-IS)'!$B$4:$G$541,4,FALSE) -> vg_msfs02 | AI294: =VLOOKUP(AG294,'스토리지_LUN(AS-IS)'!$B$4:$G$541,6,FALSE) -> 220 | AJ294: =VLOOKUP($AG294,'스토리지_LUN(TO-BE)'!$B$2:$G$347,4,FALSE) -> 00:76 | AM294: =VLOOKUP(F294,$F$580:$AM$608,34,FALSE) -> NB-DR-RDMP-0FBC-PKCMSSMR | AN294: =VLOOKUP(SUBSTITUTE(Q294,":",""),'naa정보-입력'!B292:C637,2,FALSE) -> #N/A | AO294: =_xlfn.CONCAT($AN$3,AN294," ","/vmfs/volumes/",AM294,"/",H294) -> #N/A | AP294: rm -f /vmfs/volumes/NB-DR-RDMP-0FBC-PKCMSSMR/pkcmssmr2/pkcmssmr2.vmdk
A295: 10.146.106.53 | B295: B-SV-PKM-RE | C295: pkmmsbkr3 | D295: 관리 | E295: 1,0 | F295: B-DR-RDMP-LUN192-PKFMSBKR | G295: naa.60060e80166221000001622100001f15 | H295: pkfmsbkr1/pkfmsbkr1.vmdk | I295: 020000000060060e801662210000016221000000724f50454e2d56 | J295: naa.60060e80166221000001622100000072 | K295: 10.146.106.53naa.60060e80166221000001622100000072 | L295: vmhba4:C0:T0:L0 | M295: 16221 | N295: 0072 | O295: 00:72 | P295: 680.00061 | Q295: =VLOOKUP($O295,'스토리지_LUN(TO-BE)'!$B$2:$G$347,4,FALSE) -> 00:72 | V295: =VLOOKUP($N295,OS_Disk!$A$2:$F$573,2,FALSE) -> pkmmsbkr3 | W295: =VLOOKUP($N295,OS_Disk!$A$2:$F$573,3,FALSE) -> hitachi_vsp0_0072 | Y295: =VLOOKUP($N295,OS_Disk!$A$2:$F$573,4,FALSE) -> sdf | Z295: =VLOOKUP($N295,OS_Disk!$A$2:$F$573,6,FALSE) -> 35.00061 | AA295: =VLOOKUP($O295,Veritas_LUN!$D$3:$J$487,2,FALSE) -> pkmmsbkr3/pkmmsbkr4 | AB295: =VLOOKUP($O295,Veritas_LUN!$D$3:$J$487,3,FALSE) -> vg_mscfs04 | AC295: =VLOOKUP($O295,Veritas_LUN!$D$3:$J$487,4,FALSE) -> 1 | AD295: =VLOOKUP($O295,Veritas_LUN!$D$3:$J$487,5,FALSE) -> 35 | AE295: =VLOOKUP($O295,Veritas_LUN!$D$3:$J$487,7,FALSE) -> vg_ms1fs01 | AF295: =VLOOKUP($O295,Veritas_LUN!$D$3:$K$487,8,FALSE) -> 00:72 | AG295: 00:72 | AH295: =VLOOKUP(AG295,'스토리지_LUN(AS-IS)'!$B$4:$G$541,4,FALSE) -> vg_ms1fs01 | AI295: =VLOOKUP(AG295,'스토리지_LUN(AS-IS)'!$B$4:$G$541,6,FALSE) -> 35 | AJ295: =VLOOKUP($AG295,'스토리지_LUN(TO-BE)'!$B$2:$G$347,4,FALSE) -> 00:72 | AM295: =VLOOKUP(F295,$F$580:$AM$608,34,FALSE) -> NB-DR-RDMP-0FB5-PKFMSBKR | AN295: =VLOOKUP(SUBSTITUTE(Q295,":",""),'naa정보-입력'!B293:C638,2,FALSE) -> #N/A | AO295: =_xlfn.CONCAT($AN$3,AN295," ","/vmfs/volumes/",AM295,"/",H295) -> #N/A | AP295: rm -f /vmfs/volumes/NB-DR-RDMP-0FB5-PKFMSBKR/pkfmsbkr1/pkfmsbkr1.vmdk
A296: 10.146.106.53 | B296: B-SV-PKM-RE | C296: pkmmsbkr3 | D296: 관리 | E296: 1,1 | F296: B-DR-RDMP-LUN193-PKFMSBKR | G296: naa.60060e80166221000001622100001f16 | H296: pkfmsbkr1/pkfmsbkr1.vmdk | I296: 020001000060060e801662210000016221000000734f50454e2d56 | J296: naa.60060e80166221000001622100000073 | K296: 10.146.106.53naa.60060e80166221000001622100000073 | L296: vmhba4:C0:T0:L1 | M296: 16221 | N296: 0073 | O296: 00:73 | P296: 210 | Q296: =VLOOKUP($O296,'스토리지_LUN(TO-BE)'!$B$2:$G$347,4,FALSE) -> 00:73 | V296: =VLOOKUP($N296,OS_Disk!$A$2:$F$573,2,FALSE) -> pkmmsbkr3 | W296: =VLOOKUP($N296,OS_Disk!$A$2:$F$573,3,FALSE) -> hitachi_vsp0_0073 | Y296: =VLOOKUP($N296,OS_Disk!$A$2:$F$573,4,FALSE) -> sdg | Z296: =VLOOKUP($N296,OS_Disk!$A$2:$F$573,6,FALSE) -> 700.00031 | AA296: =VLOOKUP($O296,Veritas_LUN!$D$3:$J$487,2,FALSE) -> pkmmsbkr3/pkmmsbkr4 | AB296: =VLOOKUP($O296,Veritas_LUN!$D$3:$J$487,3,FALSE) -> vg_msfs01 | AC296: =VLOOKUP($O296,Veritas_LUN!$D$3:$J$487,4,FALSE) -> 1 | AD296: =VLOOKUP($O296,Veritas_LUN!$D$3:$J$487,5,FALSE) -> 700 | AE296: =VLOOKUP($O296,Veritas_LUN!$D$3:$J$487,7,FALSE) -> vg_mscfs01 | AF296: =VLOOKUP($O296,Veritas_LUN!$D$3:$K$487,8,FALSE) -> 00:73 | AG296: 00:73 | AH296: =VLOOKUP(AG296,'스토리지_LUN(AS-IS)'!$B$4:$G$541,4,FALSE) -> vg_mscfs01 | AI296: =VLOOKUP(AG296,'스토리지_LUN(AS-IS)'!$B$4:$G$541,6,FALSE) -> 700 | AJ296: =VLOOKUP($AG296,'스토리지_LUN(TO-BE)'!$B$2:$G$347,4,FALSE) -> 00:73 | AM296: =VLOOKUP(F296,$F$580:$AM$608,34,FALSE) -> NB-DR-RDMP-0FB6-PKFMSBKR | AN296: =VLOOKUP(SUBSTITUTE(Q296,":",""),'naa정보-입력'!B294:C639,2,FALSE) -> #N/A | AO296: =_xlfn.CONCAT($AN$3,AN296," ","/vmfs/volumes/",AM296,"/",H296) -> #N/A | AP296: rm -f /vmfs/volumes/NB-DR-RDMP-0FB6-PKFMSBKR/pkfmsbkr1/pkfmsbkr1.vmdk
A297: 10.146.106.53 | B297: B-SV-PKM-RE | C297: pkmmsbkr3 | D297: 관리 | E297: 1,2 | F297: B-DR-RDMP-LUN193-PKFMSBKR | G297: naa.60060e80166221000001622100001f16 | H297: pkfmsbkr1/pkfmsbkr1_1.vmdk | I297: 020002000060060e801662210000016221000000744f50454e2d56 | J297: naa.60060e80166221000001622100000074 | K297: 10.146.106.53naa.60060e80166221000001622100000074 | L297: vmhba4:C0:T0:L2 | M297: 16221 | N297: 0074 | O297: 00:74 | P297: 65.00061 | Q297: =VLOOKUP($O297,'스토리지_LUN(TO-BE)'!$B$2:$G$347,4,FALSE) -> 00:74 | V297: =VLOOKUP($N297,OS_Disk!$A$2:$F$573,2,FALSE) -> pkmmsbkr3 | W297: =VLOOKUP($N297,OS_Disk!$A$2:$F$573,3,FALSE) -> hitachi_vsp0_0074 | Y297: =VLOOKUP($N297,OS_Disk!$A$2:$F$573,4,FALSE) -> sdh | Z297: =VLOOKUP($N297,OS_Disk!$A$2:$F$573,6,FALSE) -> 210 | AA297: =VLOOKUP($O297,Veritas_LUN!$D$3:$J$487,2,FALSE) -> pkmmsbkr3/pkmmsbkr4 | AB297: =VLOOKUP($O297,Veritas_LUN!$D$3:$J$487,3,FALSE) -> vg_mscfs01 | AC297: =VLOOKUP($O297,Veritas_LUN!$D$3:$J$487,4,FALSE) -> 1 | AD297: =VLOOKUP($O297,Veritas_LUN!$D$3:$J$487,5,FALSE) -> 210 | AE297: =VLOOKUP($O297,Veritas_LUN!$D$3:$J$487,7,FALSE) -> vg_mscfs02 | AF297: =VLOOKUP($O297,Veritas_LUN!$D$3:$K$487,8,FALSE) -> 00:74 | AG297: 00:74 | AH297: =VLOOKUP(AG297,'스토리지_LUN(AS-IS)'!$B$4:$G$541,4,FALSE) -> vg_mscfs02 | AI297: =VLOOKUP(AG297,'스토리지_LUN(AS-IS)'!$B$4:$G$541,6,FALSE) -> 210 | AJ297: =VLOOKUP($AG297,'스토리지_LUN(TO-BE)'!$B$2:$G$347,4,FALSE) -> 00:74 | AM297: =VLOOKUP(F297,$F$580:$AM$608,34,FALSE) -> NB-DR-RDMP-0FB6-PKFMSBKR | AN297: =VLOOKUP(SUBSTITUTE(Q297,":",""),'naa정보-입력'!B295:C640,2,FALSE) -> #N/A | AO297: =_xlfn.CONCAT($AN$3,AN297," ","/vmfs/volumes/",AM297,"/",H297) -> #N/A | AP297: rm -f /vmfs/volumes/NB-DR-RDMP-0FB6-PKFMSBKR/pkfmsbkr1/pkfmsbkr1_1.vmdk
